Workbook

Sheet MAGUIKAY ES
A5: Republic of the Philippines
A6: Department of Education
A8: SCHOOLS DIVISION OF MANDAUE CITY
A10: CURRICULUM, INSTRUCTION, AND ASSESSMENT MONITORING CHECKLIST
A11: School: | B11: MAGUIKAY ELEMENTARY SCHOOL
A12: Quarter: | B12: TERM 1
A13: Monitored by:
A14: A. CURRICULUM–INSTRUCTION–ASSESSMENT ALIGNMENT
A15: Indicator | B15: Yes | C15: No | D15: Remarks/Evidence
A16: 1. MELC mapping (Planned vs Taught vs Assessed) is conducted | AA16: FALSE | AB16: FALSE | AC16: =IF(AA16="","",IF(AA16=TRUE,1,0)) -> 0 | AD16: =IF(AB16="","",IF(AB16=TRUE,0.5,0)) -> 0 | AE16: =SUM(AC16:AD16) -> 0 | AF16: =IF(AE16=1,AC16,0) -> 0 | AG16: =IF(AE16=1,AD16,0) -> 0 | AH16: =IF(AD16=0,"",IF(AD16=1,2,0))
A17: 2. All MELCs are reflected in lesson plans | AA17: FALSE | AB17: FALSE | AC17: =IF(AA17="","",IF(AA17=TRUE,1,0)) -> 0 | AD17: =IF(AB17="","",IF(AB17=TRUE,0.5,0)) -> 0 | AE17: =SUM(AC17:AD17) -> 0 | AF17: =IF(AE17=1,AC17,0) -> 0 | AG17: =IF(AE17=1,AD17,0) -> 0 | AH17: =IF(AD17=0,"",IF(AD17=1,2,0))
A18: 3. Assessments are aligned with taught MELCs | AA18: FALSE | AB18: FALSE | AC18: =IF(AA18="","",IF(AA18=TRUE,1,0)) -> 0 | AD18: =IF(AB18="","",IF(AB18=TRUE,0.5,0)) -> 0 | AE18: =SUM(AC18:AD18) -> 0 | AF18: =IF(AE18=1,AC18,0) -> 0 | AG18: =IF(AE18=1,AD18,0) -> 0 | AH18: =IF(AD18=0,"",IF(AD18=1,2,0))
A19: 4. High-frequency NAT MELCs are prioritized | AA19: FALSE | AB19: FALSE | AC19: =IF(AA19="","",IF(AA19=TRUE,1,0)) -> 0 | AD19: =IF(AB19="","",IF(AB19=TRUE,0.5,0)) -> 0 | AE19: =SUM(AC19:AD19) -> 0 | AF19: =IF(AE19=1,AC19,0) -> 0 | AG19: =IF(AE19=1,AD19,0) -> 0 | AH19: =IF(AD19=0,"",IF(AD19=1,2,0))
AA20: FALSE | AB20: FALSE | AC20: =IF(AA20="","",IF(AA20=TRUE,1,0)) -> 0 | AD20: =IF(AB20="","",IF(AB20=TRUE,0.5,0)) -> 0 | AE20: =SUM(AC20:AD20) -> 0 | AF20: =IF(AE20=1,AC20,0) -> 0 | AG20: =IF(AE20=1,AD20,0) -> 0 | AH20: =IF(AD20=0,"",IF(AD20=1,2,0))
A21: B. ASSESSMENT QUALITY (HOTS-BASED) | B21: =AF21 -> 0 | C21: =AG21 -> 0 | AC21: =IF(AA21="","",IF(AA21=TRUE,1,0)) | AD21: =IF(AB21="","",IF(AB21=TRUE,1,0)) | AF21: =SUM(AF16:AF20) -> 0 | AG21: =SUM(AG16:AG20) -> 0
A22: Indicator | B22: Yes | C22: No | D22: Remarks/Evidence | AC22: =IF(AA22="","",IF(AA22=TRUE,1,0)) | AD22: =IF(AB22="","",IF(AB22=TRUE,1,0))
A23: 1. Classroom tests include 40–50% HOTS items | AA23: FALSE | AB23: FALSE | AC23: =IF(AA23="","",IF(AA23=TRUE,1,0)) -> 0 | AD23: =IF(AB23="","",IF(AB23=TRUE,0.5,0)) -> 0 | AE23: =SUM(AC23:AD23) -> 0 | AF23: =IF(AE23=1,AC23,0) -> 0 | AG23: =IF(AE23=1,AD23,0) -> 0 | AH23: =IF(AD23=0,"",IF(AD23=1,2,0))
A24: 2. Test items reflect application, analysis, interpretation | AA24: FALSE | AB24: FALSE | AC24: =IF(AA24="","",IF(AA24=TRUE,1,0)) -> 0 | AD24: =IF(AB24="","",IF(AB24=TRUE,0.5,0)) -> 0 | AE24: =SUM(AC24:AD24) -> 0 | AF24: =IF(AE24=1,AC24,0) -> 0 | AG24: =IF(AE24=1,AD24,0) -> 0 | AH24: =IF(AD24=0,"",IF(AD24=1,2,0))
A25: 3. NAT-like test items are used | AA25: FALSE | AB25: FALSE | AC25: =IF(AA25="","",IF(AA25=TRUE,1,0)) -> 0 | AD25: =IF(AB25="","",IF(AB25=TRUE,0.5,0)) -> 0 | AE25: =SUM(AC25:AD25) -> 0 | AF25: =IF(AE25=1,AC25,0) -> 0 | AG25: =IF(AE25=1,AD25,0) -> 0 | AH25: =IF(AD25=0,"",IF(AD25=1,2,0))
A26: 4. Item analysis is conducted after assessments | AA26: FALSE | AB26: FALSE | AC26: =IF(AA26="","",IF(AA26=TRUE,1,0)) -> 0 | AD26: =IF(AB26="","",IF(AB26=TRUE,0.5,0)) -> 0 | AE26: =SUM(AC26:AD26) -> 0 | AF26: =IF(AE26=1,AC26,0) -> 0 | AG26: =IF(AE26=1,AD26,0) -> 0 | AH26: =IF(AD26=0,"",IF(AD26=1,2,0))
AA27: FALSE | AB27: FALSE | AC27: =IF(AA27="","",IF(AA27=TRUE,1,0)) -> 0 | AD27: =IF(AB27="","",IF(AB27=TRUE,0.5,0)) -> 0 | AE27: =SUM(AC27:AD27) -> 0 | AF27: =IF(AE27=1,AC27,0) -> 0 | AG27: =IF(AE27=1,AD27,0) -> 0 | AH27: =IF(AD27=0,"",IF(AD27=1,2,0))
A28: C. READING ACROSS LEARNING AREAS | B28: =AF28 -> 0 | C28: =AG28 -> 0 | AC28: =IF(AA28="","",IF(AA28=TRUE,1,0)) | AD28: =IF(AB28="","",IF(AB28=TRUE,1,0)) | AF28: =SUM(AF23:AF27) -> 0 | AG28: =SUM(AG23:AG27) -> 0
A29: Indicator | B29: Yes | C29: No | D29: Remarks/Evidence | AC29: =IF(AA29="","",IF(AA29=TRUE,1,0)) | AD29: =IF(AB29="","",IF(AB29=TRUE,1,0))
A30: 1. Reading strategies are integrated in all subjects | AA30: FALSE | AB30: FALSE | AC30: =IF(AA30="","",IF(AA30=TRUE,1,0)) -> 0 | AD30: =IF(AB30="","",IF(AB30=TRUE,0.5,0)) -> 0 | AE30: =SUM(AC30:AD30) -> 0 | AF30: =IF(AE30=1,AC30,0) -> 0 | AG30: =IF(AE30=1,AD30,0) -> 0 | AH30: =IF(AD30=0,"",IF(AD30=1,2,0))
A31: 2. Vocabulary is pre-taught before lessons | AA31: FALSE | AB31: FALSE | AC31: =IF(AA31="","",IF(AA31=TRUE,1,0)) -> 0 | AD31: =IF(AB31="","",IF(AB31=TRUE,0.5,0)) -> 0 | AE31: =SUM(AC31:AD31) -> 0 | AF31: =IF(AE31=1,AC31,0) -> 0 | AG31: =IF(AE31=1,AD31,0) -> 0 | AH31: =IF(AD31=0,"",IF(AD31=1,2,0))
A32: 3. Learners explain answers in words | AA32: FALSE | AB32: FALSE | AC32: =IF(AA32="","",IF(AA32=TRUE,1,0)) -> 0 | AD32: =IF(AB32="","",IF(AB32=TRUE,0.5,0)) -> 0 | AE32: =SUM(AC32:AD32) -> 0 | AF32: =IF(AE32=1,AC32,0) -> 0 | AG32: =IF(AE32=1,AD32,0) -> 0 | AH32: =IF(AD32=0,"",IF(AD32=1,2,0))
A33: 4. Learners justify solutions/answers | AA33: FALSE | AB33: FALSE | AC33: =IF(AA33="","",IF(AA33=TRUE,1,0)) -> 0 | AD33: =IF(AB33="","",IF(AB33=TRUE,0.5,0)) -> 0 | AE33: =SUM(AC33:AD33) -> 0 | AF33: =IF(AE33=1,AC33,0) -> 0 | AG33: =IF(AE33=1,AD33,0) -> 0 | AH33: =IF(AD33=0,"",IF(AD33=1,2,0))
AA34: FALSE | AB34: FALSE | AC34: =IF(AA34="","",IF(AA34=TRUE,1,0)) -> 0 | AD34: =IF(AB34="","",IF(AB34=TRUE,0.5,0)) -> 0 | AE34: =SUM(AC34:AD34) -> 0 | AF34: =IF(AE34=1,AC34,0) -> 0 | AG34: =IF(AE34=1,AD34,0) -> 0 | AH34: =IF(AD34=0,"",IF(AD34=1,2,0))
A35: D. TARGETED REMEDIATION | B35: =AF35 -> 0 | C35: =AG35 -> 0 | AC35: =IF(AA35="","",IF(AA35=TRUE,1,0)) | AD35: =IF(AB35="","",IF(AB35=TRUE,1,0)) | AF35: =SUM(AF30:AF34) -> 0 | AG35: =SUM(AG30:AG34) -> 0
A36: Indicator | B36: Yes | C36: No | D36: Remarks/Evidence | AC36: =IF(AA36="","",IF(AA36=TRUE,1,0)) | AD36: =IF(AB36="","",IF(AB36=TRUE,1,0))
A37: 1. Item analysis identifies specific MELC gaps | AA37: FALSE | AB37: FALSE | AC37: =IF(AA37="","",IF(AA37=TRUE,1,0)) -> 0 | AD37: =IF(AB37="","",IF(AB37=TRUE,0.5,0)) -> 0 | AE37: =SUM(AC37:AD37) -> 0 | AF37: =IF(AE37=1,AC37,0) -> 0 | AG37: =IF(AE37=1,AD37,0) -> 0 | AH37: =IF(AD37=0,"",IF(AD37=1,2,0))
A38: 2. Learners are grouped based on skill gaps | AA38: FALSE | AB38: FALSE | AC38: =IF(AA38="","",IF(AA38=TRUE,1,0)) -> 0 | AD38: =IF(AB38="","",IF(AB38=TRUE,0.5,0)) -> 0 | AE38: =SUM(AC38:AD38) -> 0 | AF38: =IF(AE38=1,AC38,0) -> 0 | AG38: =IF(AE38=1,AD38,0) -> 0 | AH38: =IF(AD38=0,"",IF(AD38=1,2,0))
A39: 3. Remediation activities are focused and MELC-based | AA39: FALSE | AB39: FALSE | AC39: =IF(AA39="","",IF(AA39=TRUE,1,0)) -> 0 | AD39: =IF(AB39="","",IF(AB39=TRUE,0.5,0)) -> 0 | AE39: =SUM(AC39:AD39) -> 0 | AF39: =IF(AE39=1,AC39,0) -> 0 | AG39: =IF(AE39=1,AD39,0) -> 0 | AH39: =IF(AD39=0,"",IF(AD39=1,2,0))
A40: 4. Progress of learners is regularly monitored | AA40: FALSE | AB40: FALSE | AC40: =IF(AA40="","",IF(AA40=TRUE,1,0)) -> 0 | AD40: =IF(AB40="","",IF(AB40=TRUE,0.5,0)) -> 0 | AE40: =SUM(AC40:AD40) -> 0 | AF40: =IF(AE40=1,AC40,0) -> 0 | AG40: =IF(AE40=1,AD40,0) -> 0 | AH40: =IF(AD40=0,"",IF(AD40=1,2,0))
AA41: FALSE | AB41: FALSE | AC41: =IF(AA41="","",IF(AA41=TRUE,1,0)) -> 0 | AD41: =IF(AB41="","",IF(AB41=TRUE,0.5,0)) -> 0 | AE41: =SUM(AC41:AD41) -> 0 | AF41: =IF(AE41=1,AC41,0) -> 0 | AG41: =IF(AE41=1,AD41,0) -> 0 | AH41: =IF(AD41=0,"",IF(AD41=1,2,0))
A42: E. DATA UTILIZATION (LAC & INSTRUCTIONAL ADJUSTMENT) | B42: =AF42 -> 0 | C42: =AG42 -> 0 | AC42: =IF(AA42="","",IF(AA42=TRUE,1,0)) | AD42: =IF(AB42="","",IF(AB42=TRUE,1,0)) | AF42: =SUM(AF37:AF41) -> 0 | AG42: =SUM(AG37:AG41) -> 0
A43: Indicator | B43: Yes | C43: No | D43: Remarks/Evidence | AC43: =IF(AA43="","",IF(AA43=TRUE,1,0)) | AD43: =IF(AB43="","",IF(AB43=TRUE,1,0))
A44: 1. Quarterly data review meetings are conducted | AA44: FALSE | AB44: FALSE | AC44: =IF(AA44="","",IF(AA44=TRUE,1,0)) -> 0 | AD44: =IF(AB44="","",IF(AB44=TRUE,0.5,0)) -> 0 | AE44: =SUM(AC44:AD44) -> 0 | AF44: =IF(AE44=1,AC44,0) -> 0 | AG44: =IF(AE44=1,AD44,0) -> 0 | AH44: =IF(AD44=0,"",IF(AD44=1,2,0))
A45: 2. LAC sessions include data discussion | AA45: FALSE | AB45: FALSE | AC45: =IF(AA45="","",IF(AA45=TRUE,1,0)) -> 0 | AD45: =IF(AB45="","",IF(AB45=TRUE,0.5,0)) -> 0 | AE45: =SUM(AC45:AD45) -> 0 | AF45: =IF(AE45=1,AC45,0) -> 0 | AG45: =IF(AE45=1,AD45,0) -> 0 | AH45: =IF(AD45=0,"",IF(AD45=1,2,0))
A46: 3. Instruction is adjusted based on data | AA46: FALSE | AB46: FALSE | AC46: =IF(AA46="","",IF(AA46=TRUE,1,0)) -> 0 | AD46: =IF(AB46="","",IF(AB46=TRUE,0.5,0)) -> 0 | AE46: =SUM(AC46:AD46) -> 0 | AF46: =IF(AE46=1,AC46,0) -> 0 | AG46: =IF(AE46=1,AD46,0) -> 0 | AH46: =IF(AD46=0,"",IF(AD46=1,2,0))
...

Sheet CABANCALAN I ES
A5: Republic of the Philippines
A6: Department of Education
A8: SCHOOLS DIVISION OF MANDAUE CITY
A10: CURRICULUM, INSTRUCTION, AND ASSESSMENT MONITORING CHECKLIST
A11: School: | B11: CABANCALAN ELEMENTARY SCHOOL 1
A12: Quarter:
A13: Monitored by:
A14: A. CURRICULUM–INSTRUCTION–ASSESSMENT ALIGNMENT
A15: Indicator | B15: Yes | C15: No | D15: Remarks/Evidence
A16: 1. MELC mapping (Planned vs Taught vs Assessed) is conducted | AA16: FALSE | AB16: FALSE | AC16: =IF(AA16="","",IF(AA16=TRUE,1,0)) -> 0 | AD16: =IF(AB16="","",IF(AB16=TRUE,0.5,0)) -> 0 | AE16: =SUM(AC16:AD16) -> 0 | AF16: =IF(AE16=1,AC16,0) -> 0 | AG16: =IF(AE16=1,AD16,0) -> 0 | AH16: =IF(AD16=0,"",IF(AD16=1,2,0))
A17: 2. All MELCs are reflected in lesson plans | AA17: FALSE | AB17: FALSE | AC17: =IF(AA17="","",IF(AA17=TRUE,1,0)) -> 0 | AD17: =IF(AB17="","",IF(AB17=TRUE,0.5,0)) -> 0 | AE17: =SUM(AC17:AD17) -> 0 | AF17: =IF(AE17=1,AC17,0) -> 0 | AG17: =IF(AE17=1,AD17,0) -> 0 | AH17: =IF(AD17=0,"",IF(AD17=1,2,0))
A18: 3. Assessments are aligned with taught MELCs | AA18: FALSE | AB18: FALSE | AC18: =IF(AA18="","",IF(AA18=TRUE,1,0)) -> 0 | AD18: =IF(AB18="","",IF(AB18=TRUE,0.5,0)) -> 0 | AE18: =SUM(AC18:AD18) -> 0 | AF18: =IF(AE18=1,AC18,0) -> 0 | AG18: =IF(AE18=1,AD18,0) -> 0 | AH18: =IF(AD18=0,"",IF(AD18=1,2,0))
A19: 4. High-frequency NAT MELCs are prioritized | AA19: FALSE | AB19: FALSE | AC19: =IF(AA19="","",IF(AA19=TRUE,1,0)) -> 0 | AD19: =IF(AB19="","",IF(AB19=TRUE,0.5,0)) -> 0 | AE19: =SUM(AC19:AD19) -> 0 | AF19: =IF(AE19=1,AC19,0) -> 0 | AG19: =IF(AE19=1,AD19,0) -> 0 | AH19: =IF(AD19=0,"",IF(AD19=1,2,0))
AA20: FALSE | AB20: FALSE | AC20: =IF(AA20="","",IF(AA20=TRUE,1,0)) -> 0 | AD20: =IF(AB20="","",IF(AB20=TRUE,0.5,0)) -> 0 | AE20: =SUM(AC20:AD20) -> 0 | AF20: =IF(AE20=1,AC20,0) -> 0 | AG20: =IF(AE20=1,AD20,0) -> 0 | AH20: =IF(AD20=0,"",IF(AD20=1,2,0))
A21: B. ASSESSMENT QUALITY (HOTS-BASED) | B21: =AF21 -> 0 | C21: =AG21 -> 0 | AC21: =IF(AA21="","",IF(AA21=TRUE,1,0)) | AD21: =IF(AB21="","",IF(AB21=TRUE,1,0)) | AF21: =SUM(AF16:AF20) -> 0 | AG21: =SUM(AG16:AG20) -> 0
A22: Indicator | B22: Yes | C22: No | D22: Remarks/Evidence | AC22: =IF(AA22="","",IF(AA22=TRUE,1,0)) | AD22: =IF(AB22="","",IF(AB22=TRUE,1,0))
A23: 1. Classroom tests include 40–50% HOTS items | AA23: FALSE | AB23: FALSE | AC23: =IF(AA23="","",IF(AA23=TRUE,1,0)) -> 0 | AD23: =IF(AB23="","",IF(AB23=TRUE,0.5,0)) -> 0 | AE23: =SUM(AC23:AD23) -> 0 | AF23: =IF(AE23=1,AC23,0) -> 0 | AG23: =IF(AE23=1,AD23,0) -> 0 | AH23: =IF(AD23=0,"",IF(AD23=1,2,0))
A24: 2. Test items reflect application, analysis, interpretation | AA24: FALSE | AB24: FALSE | AC24: =IF(AA24="","",IF(AA24=TRUE,1,0)) -> 0 | AD24: =IF(AB24="","",IF(AB24=TRUE,0.5,0)) -> 0 | AE24: =SUM(AC24:AD24) -> 0 | AF24: =IF(AE24=1,AC24,0) -> 0 | AG24: =IF(AE24=1,AD24,0) -> 0 | AH24: =IF(AD24=0,"",IF(AD24=1,2,0))
A25: 3. NAT-like test items are used | AA25: FALSE | AB25: FALSE | AC25: =IF(AA25="","",IF(AA25=TRUE,1,0)) -> 0 | AD25: =IF(AB25="","",IF(AB25=TRUE,0.5,0)) -> 0 | AE25: =SUM(AC25:AD25) -> 0 | AF25: =IF(AE25=1,AC25,0) -> 0 | AG25: =IF(AE25=1,AD25,0) -> 0 | AH25: =IF(AD25=0,"",IF(AD25=1,2,0))
A26: 4. Item analysis is conducted after assessments | AA26: FALSE | AB26: FALSE | AC26: =IF(AA26="","",IF(AA26=TRUE,1,0)) -> 0 | AD26: =IF(AB26="","",IF(AB26=TRUE,0.5,0)) -> 0 | AE26: =SUM(AC26:AD26) -> 0 | AF26: =IF(AE26=1,AC26,0) -> 0 | AG26: =IF(AE26=1,AD26,0) -> 0 | AH26: =IF(AD26=0,"",IF(AD26=1,2,0))
AA27: FALSE | AB27: FALSE | AC27: =IF(AA27="","",IF(AA27=TRUE,1,0)) -> 0 | AD27: =IF(AB27="","",IF(AB27=TRUE,0.5,0)) -> 0 | AE27: =SUM(AC27:AD27) -> 0 | AF27: =IF(AE27=1,AC27,0) -> 0 | AG27: =IF(AE27=1,AD27,0) -> 0 | AH27: =IF(AD27=0,"",IF(AD27=1,2,0))
A28: C. READING ACROSS LEARNING AREAS | B28: =AF28 -> 0 | C28: =AG28 -> 0 | AC28: =IF(AA28="","",IF(AA28=TRUE,1,0)) | AD28: =IF(AB28="","",IF(AB28=TRUE,1,0)) | AF28: =SUM(AF23:AF27) -> 0 | AG28: =SUM(AG23:AG27) -> 0
A29: Indicator | B29: Yes | C29: No | D29: Remarks/Evidence | AC29: =IF(AA29="","",IF(AA29=TRUE,1,0)) | AD29: =IF(AB29="","",IF(AB29=TRUE,1,0))
A30: 1. Reading strategies are integrated in all subjects | AA30: FALSE | AB30: FALSE | AC30: =IF(AA30="","",IF(AA30=TRUE,1,0)) -> 0 | AD30: =IF(AB30="","",IF(AB30=TRUE,0.5,0)) -> 0 | AE30: =SUM(AC30:AD30) -> 0 | AF30: =IF(AE30=1,AC30,0) -> 0 | AG30: =IF(AE30=1,AD30,0) -> 0 | AH30: =IF(AD30=0,"",IF(AD30=1,2,0))
A31: 2. Vocabulary is pre-taught before lessons | AA31: FALSE | AB31: FALSE | AC31: =IF(AA31="","",IF(AA31=TRUE,1,0)) -> 0 | AD31: =IF(AB31="","",IF(AB31=TRUE,0.5,0)) -> 0 | AE31: =SUM(AC31:AD31) -> 0 | AF31: =IF(AE31=1,AC31,0) -> 0 | AG31: =IF(AE31=1,AD31,0) -> 0 | AH31: =IF(AD31=0,"",IF(AD31=1,2,0))
A32: 3. Learners explain answers in words | AA32: FALSE | AB32: FALSE | AC32: =IF(AA32="","",IF(AA32=TRUE,1,0)) -> 0 | AD32: =IF(AB32="","",IF(AB32=TRUE,0.5,0)) -> 0 | AE32: =SUM(AC32:AD32) -> 0 | AF32: =IF(AE32=1,AC32,0) -> 0 | AG32: =IF(AE32=1,AD32,0) -> 0 | AH32: =IF(AD32=0,"",IF(AD32=1,2,0))
A33: 4. Learners justify solutions/answers | AA33: FALSE | AB33: FALSE | AC33: =IF(AA33="","",IF(AA33=TRUE,1,0)) -> 0 | AD33: =IF(AB33="","",IF(AB33=TRUE,0.5,0)) -> 0 | AE33: =SUM(AC33:AD33) -> 0 | AF33: =IF(AE33=1,AC33,0) -> 0 | AG33: =IF(AE33=1,AD33,0) -> 0 | AH33: =IF(AD33=0,"",IF(AD33=1,2,0))
AA34: FALSE | AB34: FALSE | AC34: =IF(AA34="","",IF(AA34=TRUE,1,0)) -> 0 | AD34: =IF(AB34="","",IF(AB34=TRUE,0.5,0)) -> 0 | AE34: =SUM(AC34:AD34) -> 0 | AF34: =IF(AE34=1,AC34,0) -> 0 | AG34: =IF(AE34=1,AD34,0) -> 0 | AH34: =IF(AD34=0,"",IF(AD34=1,2,0))
A35: D. TARGETED REMEDIATION | B35: =AF35 -> 0 | C35: =AG35 -> 0 | AC35: =IF(AA35="","",IF(AA35=TRUE,1,0)) | AD35: =IF(AB35="","",IF(AB35=TRUE,1,0)) | AF35: =SUM(AF30:AF34) -> 0 | AG35: =SUM(AG30:AG34) -> 0
A36: Indicator | B36: Yes | C36: No | D36: Remarks/Evidence | AC36: =IF(AA36="","",IF(AA36=TRUE,1,0)) | AD36: =IF(AB36="","",IF(AB36=TRUE,1,0))
A37: 1. Item analysis identifies specific MELC gaps | AA37: FALSE | AB37: FALSE | AC37: =IF(AA37="","",IF(AA37=TRUE,1,0)) -> 0 | AD37: =IF(AB37="","",IF(AB37=TRUE,0.5,0)) -> 0 | AE37: =SUM(AC37:AD37) -> 0 | AF37: =IF(AE37=1,AC37,0) -> 0 | AG37: =IF(AE37=1,AD37,0) -> 0 | AH37: =IF(AD37=0,"",IF(AD37=1,2,0))
A38: 2. Learners are grouped based on skill gaps | AA38: FALSE | AB38: FALSE | AC38: =IF(AA38="","",IF(AA38=TRUE,1,0)) -> 0 | AD38: =IF(AB38="","",IF(AB38=TRUE,0.5,0)) -> 0 | AE38: =SUM(AC38:AD38) -> 0 | AF38: =IF(AE38=1,AC38,0) -> 0 | AG38: =IF(AE38=1,AD38,0) -> 0 | AH38: =IF(AD38=0,"",IF(AD38=1,2,0))
A39: 3. Remediation activities are focused and MELC-based | AA39: FALSE | AB39: FALSE | AC39: =IF(AA39="","",IF(AA39=TRUE,1,0)) -> 0 | AD39: =IF(AB39="","",IF(AB39=TRUE,0.5,0)) -> 0 | AE39: =SUM(AC39:AD39) -> 0 | AF39: =IF(AE39=1,AC39,0) -> 0 | AG39: =IF(AE39=1,AD39,0) -> 0 | AH39: =IF(AD39=0,"",IF(AD39=1,2,0))
A40: 4. Progress of learners is regularly monitored | AA40: FALSE | AB40: FALSE | AC40: =IF(AA40="","",IF(AA40=TRUE,1,0)) -> 0 | AD40: =IF(AB40="","",IF(AB40=TRUE,0.5,0)) -> 0 | AE40: =SUM(AC40:AD40) -> 0 | AF40: =IF(AE40=1,AC40,0) -> 0 | AG40: =IF(AE40=1,AD40,0) -> 0 | AH40: =IF(AD40=0,"",IF(AD40=1,2,0))
AA41: FALSE | AB41: FALSE | AC41: =IF(AA41="","",IF(AA41=TRUE,1,0)) -> 0 | AD41: =IF(AB41="","",IF(AB41=TRUE,0.5,0)) -> 0 | AE41: =SUM(AC41:AD41) -> 0 | AF41: =IF(AE41=1,AC41,0) -> 0 | AG41: =IF(AE41=1,AD41,0) -> 0 | AH41: =IF(AD41=0,"",IF(AD41=1,2,0))
A42: E. DATA UTILIZATION (LAC & INSTRUCTIONAL ADJUSTMENT) | B42: =AF42 -> 0 | C42: =AG42 -> 0 | AC42: =IF(AA42="","",IF(AA42=TRUE,1,0)) | AD42: =IF(AB42="","",IF(AB42=TRUE,1,0)) | AF42: =SUM(AF37:AF41) -> 0 | AG42: =SUM(AG37:AG41) -> 0
A43: Indicator | B43: Yes | C43: No | D43: Remarks/Evidence | AC43: =IF(AA43="","",IF(AA43=TRUE,1,0)) | AD43: =IF(AB43="","",IF(AB43=TRUE,1,0))
A44: 1. Quarterly data review meetings are conducted | AA44: FALSE | AB44: FALSE | AC44: =IF(AA44="","",IF(AA44=TRUE,1,0)) -> 0 | AD44: =IF(AB44="","",IF(AB44=TRUE,0.5,0)) -> 0 | AE44: =SUM(AC44:AD44) -> 0 | AF44: =IF(AE44=1,AC44,0) -> 0 | AG44: =IF(AE44=1,AD44,0) -> 0 | AH44: =IF(AD44=0,"",IF(AD44=1,2,0))
A45: 2. LAC sessions include data discussion | AA45: FALSE | AB45: FALSE | AC45: =IF(AA45="","",IF(AA45=TRUE,1,0)) -> 0 | AD45: =IF(AB45="","",IF(AB45=TRUE,0.5,0)) -> 0 | AE45: =SUM(AC45:AD45) -> 0 | AF45: =IF(AE45=1,AC45,0) -> 0 | AG45: =IF(AE45=1,AD45,0) -> 0 | AH45: =IF(AD45=0,"",IF(AD45=1,2,0))
A46: 3. Instruction is adjusted based on data | AA46: FALSE | AB46: FALSE | AC46: =IF(AA46="","",IF(AA46=TRUE,1,0)) -> 0 | AD46: =IF(AB46="","",IF(AB46=TRUE,0.5,0)) -> 0 | AE46: =SUM(AC46:AD46) -> 0 | AF46: =IF(AE46=1,AC46,0) -> 0 | AG46: =IF(AE46=1,AD46,0) -> 0 | AH46: =IF(AD46=0,"",IF(AD46=1,2,0))
...

Sheet TABOK ES 1
A5: Republic of the Philippines
A6: Department of Education
A8: SCHOOLS DIVISION OF MANDAUE CITY
A10: CURRICULUM, INSTRUCTION, AND ASSESSMENT MONITORING CHECKLIST
A11: School: | B11: TABOK ELEMENTARY SCHOOL 1
A12: Quarter: | B12: TERM 1
A13: Monitored by: | B13: MARY JEAN B. CODIÑERA
A14: A. CURRICULUM–INSTRUCTION–ASSESSMENT ALIGNMENT
A15: Indicator | B15: Yes | C15: No | D15: Remarks/Evidence
A16: 1. MELC mapping (Planned vs Taught vs Assessed) is conducted | AA16: FALSE | AB16: TRUE | AC16: =IF(AA16="","",IF(AA16=TRUE,1,0)) -> 0 | AD16: =IF(AB16="","",IF(AB16=TRUE,0.5,0)) -> 0.5 | AE16: =SUM(AC16:AD16) -> 0.5 | AF16: =IF(AE16=1,AC16,0) -> 0 | AG16: =IF(AE16=1,AD16,0) -> 0 | AH16: =IF(AD16=0,"",IF(AD16=1,2,0)) -> 0
A17: 2. All MELCs are reflected in lesson plans | AA17: TRUE | AB17: FALSE | AC17: =IF(AA17="","",IF(AA17=TRUE,1,0)) -> 1 | AD17: =IF(AB17="","",IF(AB17=TRUE,0.5,0)) -> 0 | AE17: =SUM(AC17:AD17) -> 1 | AF17: =IF(AE17=1,AC17,0) -> 1 | AG17: =IF(AE17=1,AD17,0) -> 0 | AH17: =IF(AD17=0,"",IF(AD17=1,2,0))
A18: 3. Assessments are aligned with taught MELCs | AA18: TRUE | AB18: FALSE | AC18: =IF(AA18="","",IF(AA18=TRUE,1,0)) -> 1 | AD18: =IF(AB18="","",IF(AB18=TRUE,0.5,0)) -> 0 | AE18: =SUM(AC18:AD18) -> 1 | AF18: =IF(AE18=1,AC18,0) -> 1 | AG18: =IF(AE18=1,AD18,0) -> 0 | AH18: =IF(AD18=0,"",IF(AD18=1,2,0))
A19: 4. High-frequency NAT MELCs are prioritized | AA19: TRUE | AB19: FALSE | AC19: =IF(AA19="","",IF(AA19=TRUE,1,0)) -> 1 | AD19: =IF(AB19="","",IF(AB19=TRUE,0.5,0)) -> 0 | AE19: =SUM(AC19:AD19) -> 1 | AF19: =IF(AE19=1,AC19,0) -> 1 | AG19: =IF(AE19=1,AD19,0) -> 0 | AH19: =IF(AD19=0,"",IF(AD19=1,2,0))
AA20: FALSE | AB20: FALSE | AC20: =IF(AA20="","",IF(AA20=TRUE,1,0)) -> 0 | AD20: =IF(AB20="","",IF(AB20=TRUE,0.5,0)) -> 0 | AE20: =SUM(AC20:AD20) -> 0 | AF20: =IF(AE20=1,AC20,0) -> 0 | AG20: =IF(AE20=1,AD20,0) -> 0 | AH20: =IF(AD20=0,"",IF(AD20=1,2,0))
A21: B. ASSESSMENT QUALITY (HOTS-BASED) | B21: =AF21 -> 3 | C21: =AG21 -> 0 | AC21: =IF(AA21="","",IF(AA21=TRUE,1,0)) | AD21: =IF(AB21="","",IF(AB21=TRUE,1,0)) | AF21: =SUM(AF16:AF20) -> 3 | AG21: =SUM(AG16:AG20) -> 0
A22: Indicator | B22: Yes | C22: No | D22: Remarks/Evidence | AC22: =IF(AA22="","",IF(AA22=TRUE,1,0)) | AD22: =IF(AB22="","",IF(AB22=TRUE,1,0))
A23: 1. Classroom tests include 40–50% HOTS items | AA23: FALSE | AB23: TRUE | AC23: =IF(AA23="","",IF(AA23=TRUE,1,0)) -> 0 | AD23: =IF(AB23="","",IF(AB23=TRUE,0.5,0)) -> 0.5 | AE23: =SUM(AC23:AD23) -> 0.5 | AF23: =IF(AE23=1,AC23,0) -> 0 | AG23: =IF(AE23=1,AD23,0) -> 0 | AH23: =IF(AD23=0,"",IF(AD23=1,2,0)) -> 0
A24: 2. Test items reflect application, analysis, interpretation | AA24: FALSE | AB24: TRUE | AC24: =IF(AA24="","",IF(AA24=TRUE,1,0)) -> 0 | AD24: =IF(AB24="","",IF(AB24=TRUE,0.5,0)) -> 0.5 | AE24: =SUM(AC24:AD24) -> 0.5 | AF24: =IF(AE24=1,AC24,0) -> 0 | AG24: =IF(AE24=1,AD24,0) -> 0 | AH24: =IF(AD24=0,"",IF(AD24=1,2,0)) -> 0
A25: 3. NAT-like test items are used | AA25: FALSE | AB25: TRUE | AC25: =IF(AA25="","",IF(AA25=TRUE,1,0)) -> 0 | AD25: =IF(AB25="","",IF(AB25=TRUE,0.5,0)) -> 0.5 | AE25: =SUM(AC25:AD25) -> 0.5 | AF25: =IF(AE25=1,AC25,0) -> 0 | AG25: =IF(AE25=1,AD25,0) -> 0 | AH25: =IF(AD25=0,"",IF(AD25=1,2,0)) -> 0
A26: 4. Item analysis is conducted after assessments | AA26: FALSE | AB26: TRUE | AC26: =IF(AA26="","",IF(AA26=TRUE,1,0)) -> 0 | AD26: =IF(AB26="","",IF(AB26=TRUE,0.5,0)) -> 0.5 | AE26: =SUM(AC26:AD26) -> 0.5 | AF26: =IF(AE26=1,AC26,0) -> 0 | AG26: =IF(AE26=1,AD26,0) -> 0 | AH26: =IF(AD26=0,"",IF(AD26=1,2,0)) -> 0
AA27: FALSE | AB27: FALSE | AC27: =IF(AA27="","",IF(AA27=TRUE,1,0)) -> 0 | AD27: =IF(AB27="","",IF(AB27=TRUE,0.5,0)) -> 0 | AE27: =SUM(AC27:AD27) -> 0 | AF27: =IF(AE27=1,AC27,0) -> 0 | AG27: =IF(AE27=1,AD27,0) -> 0 | AH27: =IF(AD27=0,"",IF(AD27=1,2,0))
A28: C. READING ACROSS LEARNING AREAS | B28: =AF28 -> 0 | C28: =AG28 -> 0 | AC28: =IF(AA28="","",IF(AA28=TRUE,1,0)) | AD28: =IF(AB28="","",IF(AB28=TRUE,1,0)) | AF28: =SUM(AF23:AF27) -> 0 | AG28: =SUM(AG23:AG27) -> 0
A29: Indicator | B29: Yes | C29: No | D29: Remarks/Evidence | AC29: =IF(AA29="","",IF(AA29=TRUE,1,0)) | AD29: =IF(AB29="","",IF(AB29=TRUE,1,0))
A30: 1. Reading strategies are integrated in all subjects | AA30: TRUE | AB30: FALSE | AC30: =IF(AA30="","",IF(AA30=TRUE,1,0)) -> 1 | AD30: =IF(AB30="","",IF(AB30=TRUE,0.5,0)) -> 0 | AE30: =SUM(AC30:AD30) -> 1 | AF30: =IF(AE30=1,AC30,0) -> 1 | AG30: =IF(AE30=1,AD30,0) -> 0 | AH30: =IF(AD30=0,"",IF(AD30=1,2,0))
A31: 2. Vocabulary is pre-taught before lessons | AA31: TRUE | AB31: FALSE | AC31: =IF(AA31="","",IF(AA31=TRUE,1,0)) -> 1 | AD31: =IF(AB31="","",IF(AB31=TRUE,0.5,0)) -> 0 | AE31: =SUM(AC31:AD31) -> 1 | AF31: =IF(AE31=1,AC31,0) -> 1 | AG31: =IF(AE31=1,AD31,0) -> 0 | AH31: =IF(AD31=0,"",IF(AD31=1,2,0))
A32: 3. Learners explain answers in words | AA32: TRUE | AB32: FALSE | AC32: =IF(AA32="","",IF(AA32=TRUE,1,0)) -> 1 | AD32: =IF(AB32="","",IF(AB32=TRUE,0.5,0)) -> 0 | AE32: =SUM(AC32:AD32) -> 1 | AF32: =IF(AE32=1,AC32,0) -> 1 | AG32: =IF(AE32=1,AD32,0) -> 0 | AH32: =IF(AD32=0,"",IF(AD32=1,2,0))
A33: 4. Learners justify solutions/answers | AA33: TRUE | AB33: FALSE | AC33: =IF(AA33="","",IF(AA33=TRUE,1,0)) -> 1 | AD33: =IF(AB33="","",IF(AB33=TRUE,0.5,0)) -> 0 | AE33: =SUM(AC33:AD33) -> 1 | AF33: =IF(AE33=1,AC33,0) -> 1 | AG33: =IF(AE33=1,AD33,0) -> 0 | AH33: =IF(AD33=0,"",IF(AD33=1,2,0))
AA34: FALSE | AB34: FALSE | AC34: =IF(AA34="","",IF(AA34=TRUE,1,0)) -> 0 | AD34: =IF(AB34="","",IF(AB34=TRUE,0.5,0)) -> 0 | AE34: =SUM(AC34:AD34) -> 0 | AF34: =IF(AE34=1,AC34,0) -> 0 | AG34: =IF(AE34=1,AD34,0) -> 0 | AH34: =IF(AD34=0,"",IF(AD34=1,2,0))
A35: D. TARGETED REMEDIATION | B35: =AF35 -> 4 | C35: =AG35 -> 0 | AC35: =IF(AA35="","",IF(AA35=TRUE,1,0)) | AD35: =IF(AB35="","",IF(AB35=TRUE,1,0)) | AF35: =SUM(AF30:AF34) -> 4 | AG35: =SUM(AG30:AG34) -> 0
A36: Indicator | B36: Yes | C36: No | D36: Remarks/Evidence | AC36: =IF(AA36="","",IF(AA36=TRUE,1,0)) | AD36: =IF(AB36="","",IF(AB36=TRUE,1,0))
A37: 1. Item analysis identifies specific MELC gaps | AA37: FALSE | AB37: TRUE | AC37: =IF(AA37="","",IF(AA37=TRUE,1,0)) -> 0 | AD37: =IF(AB37="","",IF(AB37=TRUE,0.5,0)) -> 0.5 | AE37: =SUM(AC37:AD37) -> 0.5 | AF37: =IF(AE37=1,AC37,0) -> 0 | AG37: =IF(AE37=1,AD37,0) -> 0 | AH37: =IF(AD37=0,"",IF(AD37=1,2,0)) -> 0
A38: 2. Learners are grouped based on skill gaps | AA38: TRUE | AB38: FALSE | AC38: =IF(AA38="","",IF(AA38=TRUE,1,0)) -> 1 | AD38: =IF(AB38="","",IF(AB38=TRUE,0.5,0)) -> 0 | AE38: =SUM(AC38:AD38) -> 1 | AF38: =IF(AE38=1,AC38,0) -> 1 | AG38: =IF(AE38=1,AD38,0) -> 0 | AH38: =IF(AD38=0,"",IF(AD38=1,2,0))
A39: 3. Remediation activities are focused and MELC-based | AA39: TRUE | AB39: FALSE | AC39: =IF(AA39="","",IF(AA39=TRUE,1,0)) -> 1 | AD39: =IF(AB39="","",IF(AB39=TRUE,0.5,0)) -> 0 | AE39: =SUM(AC39:AD39) -> 1 | AF39: =IF(AE39=1,AC39,0) -> 1 | AG39: =IF(AE39=1,AD39,0) -> 0 | AH39: =IF(AD39=0,"",IF(AD39=1,2,0))
A40: 4. Progress of learners is regularly monitored | AA40: TRUE | AB40: FALSE | AC40: =IF(AA40="","",IF(AA40=TRUE,1,0)) -> 1 | AD40: =IF(AB40="","",IF(AB40=TRUE,0.5,0)) -> 0 | AE40: =SUM(AC40:AD40) -> 1 | AF40: =IF(AE40=1,AC40,0) -> 1 | AG40: =IF(AE40=1,AD40,0) -> 0 | AH40: =IF(AD40=0,"",IF(AD40=1,2,0))
AA41: FALSE | AB41: FALSE | AC41: =IF(AA41="","",IF(AA41=TRUE,1,0)) -> 0 | AD41: =IF(AB41="","",IF(AB41=TRUE,0.5,0)) -> 0 | AE41: =SUM(AC41:AD41) -> 0 | AF41: =IF(AE41=1,AC41,0) -> 0 | AG41: =IF(AE41=1,AD41,0) -> 0 | AH41: =IF(AD41=0,"",IF(AD41=1,2,0))
A42: E. DATA UTILIZATION (LAC & INSTRUCTIONAL ADJUSTMENT) | B42: =AF42 -> 3 | C42: =AG42 -> 0 | AC42: =IF(AA42="","",IF(AA42=TRUE,1,0)) | AD42: =IF(AB42="","",IF(AB42=TRUE,1,0)) | AF42: =SUM(AF37:AF41) -> 3 | AG42: =SUM(AG37:AG41) -> 0
A43: Indicator | B43: Yes | C43: No | D43: Remarks/Evidence | AC43: =IF(AA43="","",IF(AA43=TRUE,1,0)) | AD43: =IF(AB43="","",IF(AB43=TRUE,1,0))
A44: 1. Quarterly data review meetings are conducted | AA44: FALSE | AB44: TRUE | AC44: =IF(AA44="","",IF(AA44=TRUE,1,0)) -> 0 | AD44: =IF(AB44="","",IF(AB44=TRUE,0.5,0)) -> 0.5 | AE44: =SUM(AC44:AD44) -> 0.5 | AF44: =IF(AE44=1,AC44,0) -> 0 | AG44: =IF(AE44=1,AD44,0) -> 0 | AH44: =IF(AD44=0,"",IF(AD44=1,2,0)) -> 0
A45: 2. LAC sessions include data discussion | AA45: FALSE | AB45: TRUE | AC45: =IF(AA45="","",IF(AA45=TRUE,1,0)) -> 0 | AD45: =IF(AB45="","",IF(AB45=TRUE,0.5,0)) -> 0.5 | AE45: =SUM(AC45:AD45) -> 0.5 | AF45: =IF(AE45=1,AC45,0) -> 0 | AG45: =IF(AE45=1,AD45,0) -> 0 | AH45: =IF(AD45=0,"",IF(AD45=1,2,0)) -> 0
A46: 3. Instruction is adjusted based on data | AA46: TRUE | AB46: FALSE | AC46: =IF(AA46="","",IF(AA46=TRUE,1,0)) -> 1 | AD46: =IF(AB46="","",IF(AB46=TRUE,0.5,0)) -> 0 | AE46: =SUM(AC46:AD46) -> 1 | AF46: =IF(AE46=1,AC46,0) -> 1 | AG46: =IF(AE46=1,AD46,0) -> 0 | AH46: =IF(AD46=0,"",IF(AD46=1,2,0))
...

Sheet TABOK ES II
A5: Republic of the Philippines
A6: Department of Education
A8: SCHOOLS DIVISION OF MANDAUE CITY
A10: CURRICULUM, INSTRUCTION, AND ASSESSMENT MONITORING CHECKLIST
A11: School: | B11: TABOK ELEMENTARY SCHOOL II
A12: Quarter:
A13: Monitored by:
A14: A. CURRICULUM–INSTRUCTION–ASSESSMENT ALIGNMENT
A15: Indicator | B15: Yes | C15: No | D15: Remarks/Evidence
A16: 1. MELC mapping (Planned vs Taught vs Assessed) is conducted | AA16: TRUE | AB16: FALSE | AC16: =IF(AA16="","",IF(AA16=TRUE,1,0)) -> 1 | AD16: =IF(AB16="","",IF(AB16=TRUE,0.5,0)) -> 0 | AE16: =SUM(AC16:AD16) -> 1 | AF16: =IF(AE16=1,AC16,0) -> 1 | AG16: =IF(AE16=1,AD16,0) -> 0 | AH16: =IF(AD16=0,"",IF(AD16=1,2,0))
A17: 2. All MELCs are reflected in lesson plans | AA17: TRUE | AB17: FALSE | AC17: =IF(AA17="","",IF(AA17=TRUE,1,0)) -> 1 | AD17: =IF(AB17="","",IF(AB17=TRUE,0.5,0)) -> 0 | AE17: =SUM(AC17:AD17) -> 1 | AF17: =IF(AE17=1,AC17,0) -> 1 | AG17: =IF(AE17=1,AD17,0) -> 0 | AH17: =IF(AD17=0,"",IF(AD17=1,2,0))
A18: 3. Assessments are aligned with taught MELCs | AA18: TRUE | AB18: FALSE | AC18: =IF(AA18="","",IF(AA18=TRUE,1,0)) -> 1 | AD18: =IF(AB18="","",IF(AB18=TRUE,0.5,0)) -> 0 | AE18: =SUM(AC18:AD18) -> 1 | AF18: =IF(AE18=1,AC18,0) -> 1 | AG18: =IF(AE18=1,AD18,0) -> 0 | AH18: =IF(AD18=0,"",IF(AD18=1,2,0))
A19: 4. High-frequency NAT MELCs are prioritized | AA19: TRUE | AB19: FALSE | AC19: =IF(AA19="","",IF(AA19=TRUE,1,0)) -> 1 | AD19: =IF(AB19="","",IF(AB19=TRUE,0.5,0)) -> 0 | AE19: =SUM(AC19:AD19) -> 1 | AF19: =IF(AE19=1,AC19,0) -> 1 | AG19: =IF(AE19=1,AD19,0) -> 0 | AH19: =IF(AD19=0,"",IF(AD19=1,2,0))
AA20: FALSE | AB20: FALSE | AC20: =IF(AA20="","",IF(AA20=TRUE,1,0)) -> 0 | AD20: =IF(AB20="","",IF(AB20=TRUE,0.5,0)) -> 0 | AE20: =SUM(AC20:AD20) -> 0 | AF20: =IF(AE20=1,AC20,0) -> 0 | AG20: =IF(AE20=1,AD20,0) -> 0 | AH20: =IF(AD20=0,"",IF(AD20=1,2,0))
A21: B. ASSESSMENT QUALITY (HOTS-BASED) | B21: =AF21 -> 4 | C21: =AG21 -> 0 | AC21: =IF(AA21="","",IF(AA21=TRUE,1,0)) | AD21: =IF(AB21="","",IF(AB21=TRUE,1,0)) | AF21: =SUM(AF16:AF20) -> 4 | AG21: =SUM(AG16:AG20) -> 0
A22: Indicator | B22: Yes | C22: No | D22: Remarks/Evidence | AC22: =IF(AA22="","",IF(AA22=TRUE,1,0)) | AD22: =IF(AB22="","",IF(AB22=TRUE,1,0))
A23: 1. Classroom tests include 40–50% HOTS items | AA23: FALSE | AB23: TRUE | AC23: =IF(AA23="","",IF(AA23=TRUE,1,0)) -> 0 | AD23: =IF(AB23="","",IF(AB23=TRUE,0.5,0)) -> 0.5 | AE23: =SUM(AC23:AD23) -> 0.5 | AF23: =IF(AE23=1,AC23,0) -> 0 | AG23: =IF(AE23=1,AD23,0) -> 0 | AH23: =IF(AD23=0,"",IF(AD23=1,2,0)) -> 0
A24: 2. Test items reflect application, analysis, interpretation | AA24: FALSE | AB24: TRUE | AC24: =IF(AA24="","",IF(AA24=TRUE,1,0)) -> 0 | AD24: =IF(AB24="","",IF(AB24=TRUE,0.5,0)) -> 0.5 | AE24: =SUM(AC24:AD24) -> 0.5 | AF24: =IF(AE24=1,AC24,0) -> 0 | AG24: =IF(AE24=1,AD24,0) -> 0 | AH24: =IF(AD24=0,"",IF(AD24=1,2,0)) -> 0
A25: 3. NAT-like test items are used | AA25: FALSE | AB25: TRUE | AC25: =IF(AA25="","",IF(AA25=TRUE,1,0)) -> 0 | AD25: =IF(AB25="","",IF(AB25=TRUE,0.5,0)) -> 0.5 | AE25: =SUM(AC25:AD25) -> 0.5 | AF25: =IF(AE25=1,AC25,0) -> 0 | AG25: =IF(AE25=1,AD25,0) -> 0 | AH25: =IF(AD25=0,"",IF(AD25=1,2,0)) -> 0
A26: 4. Item analysis is conducted after assessments | AA26: FALSE | AB26: TRUE | AC26: =IF(AA26="","",IF(AA26=TRUE,1,0)) -> 0 | AD26: =IF(AB26="","",IF(AB26=TRUE,0.5,0)) -> 0.5 | AE26: =SUM(AC26:AD26) -> 0.5 | AF26: =IF(AE26=1,AC26,0) -> 0 | AG26: =IF(AE26=1,AD26,0) -> 0 | AH26: =IF(AD26=0,"",IF(AD26=1,2,0)) -> 0
AA27: FALSE | AB27: FALSE | AC27: =IF(AA27="","",IF(AA27=TRUE,1,0)) -> 0 | AD27: =IF(AB27="","",IF(AB27=TRUE,0.5,0)) -> 0 | AE27: =SUM(AC27:AD27) -> 0 | AF27: =IF(AE27=1,AC27,0) -> 0 | AG27: =IF(AE27=1,AD27,0) -> 0 | AH27: =IF(AD27=0,"",IF(AD27=1,2,0))
A28: C. READING ACROSS LEARNING AREAS | B28: =AF28 -> 0 | C28: =AG28 -> 0 | AC28: =IF(AA28="","",IF(AA28=TRUE,1,0)) | AD28: =IF(AB28="","",IF(AB28=TRUE,1,0)) | AF28: =SUM(AF23:AF27) -> 0 | AG28: =SUM(AG23:AG27) -> 0
A29: Indicator | B29: Yes | C29: No | D29: Remarks/Evidence | AC29: =IF(AA29="","",IF(AA29=TRUE,1,0)) | AD29: =IF(AB29="","",IF(AB29=TRUE,1,0))
A30: 1. Reading strategies are integrated in all subjects | AA30: TRUE | AB30: FALSE | AC30: =IF(AA30="","",IF(AA30=TRUE,1,0)) -> 1 | AD30: =IF(AB30="","",IF(AB30=TRUE,0.5,0)) -> 0 | AE30: =SUM(AC30:AD30) -> 1 | AF30: =IF(AE30=1,AC30,0) -> 1 | AG30: =IF(AE30=1,AD30,0) -> 0 | AH30: =IF(AD30=0,"",IF(AD30=1,2,0))
A31: 2. Vocabulary is pre-taught before lessons | AA31: TRUE | AB31: FALSE | AC31: =IF(AA31="","",IF(AA31=TRUE,1,0)) -> 1 | AD31: =IF(AB31="","",IF(AB31=TRUE,0.5,0)) -> 0 | AE31: =SUM(AC31:AD31) -> 1 | AF31: =IF(AE31=1,AC31,0) -> 1 | AG31: =IF(AE31=1,AD31,0) -> 0 | AH31: =IF(AD31=0,"",IF(AD31=1,2,0))
A32: 3. Learners explain answers in words | AA32: FALSE | AB32: TRUE | AC32: =IF(AA32="","",IF(AA32=TRUE,1,0)) -> 0 | AD32: =IF(AB32="","",IF(AB32=TRUE,0.5,0)) -> 0.5 | AE32: =SUM(AC32:AD32) -> 0.5 | AF32: =IF(AE32=1,AC32,0) -> 0 | AG32: =IF(AE32=1,AD32,0) -> 0 | AH32: =IF(AD32=0,"",IF(AD32=1,2,0)) -> 0
A33: 4. Learners justify solutions/answers | AA33: FALSE | AB33: TRUE | AC33: =IF(AA33="","",IF(AA33=TRUE,1,0)) -> 0 | AD33: =IF(AB33="","",IF(AB33=TRUE,0.5,0)) -> 0.5 | AE33: =SUM(AC33:AD33) -> 0.5 | AF33: =IF(AE33=1,AC33,0) -> 0 | AG33: =IF(AE33=1,AD33,0) -> 0 | AH33: =IF(AD33=0,"",IF(AD33=1,2,0)) -> 0
AA34: FALSE | AB34: FALSE | AC34: =IF(AA34="","",IF(AA34=TRUE,1,0)) -> 0 | AD34: =IF(AB34="","",IF(AB34=TRUE,0.5,0)) -> 0 | AE34: =SUM(AC34:AD34) -> 0 | AF34: =IF(AE34=1,AC34,0) -> 0 | AG34: =IF(AE34=1,AD34,0) -> 0 | AH34: =IF(AD34=0,"",IF(AD34=1,2,0))
A35: D. TARGETED REMEDIATION | B35: =AF35 -> 2 | C35: =AG35 -> 0 | AC35: =IF(AA35="","",IF(AA35=TRUE,1,0)) | AD35: =IF(AB35="","",IF(AB35=TRUE,1,0)) | AF35: =SUM(AF30:AF34) -> 2 | AG35: =SUM(AG30:AG34) -> 0
A36: Indicator | B36: Yes | C36: No | D36: Remarks/Evidence | AC36: =IF(AA36="","",IF(AA36=TRUE,1,0)) | AD36: =IF(AB36="","",IF(AB36=TRUE,1,0))
A37: 1. Item analysis identifies specific MELC gaps | AA37: TRUE | AB37: FALSE | AC37: =IF(AA37="","",IF(AA37=TRUE,1,0)) -> 1 | AD37: =IF(AB37="","",IF(AB37=TRUE,0.5,0)) -> 0 | AE37: =SUM(AC37:AD37) -> 1 | AF37: =IF(AE37=1,AC37,0) -> 1 | AG37: =IF(AE37=1,AD37,0) -> 0 | AH37: =IF(AD37=0,"",IF(AD37=1,2,0))
A38: 2. Learners are grouped based on skill gaps | AA38: TRUE | AB38: FALSE | AC38: =IF(AA38="","",IF(AA38=TRUE,1,0)) -> 1 | AD38: =IF(AB38="","",IF(AB38=TRUE,0.5,0)) -> 0 | AE38: =SUM(AC38:AD38) -> 1 | AF38: =IF(AE38=1,AC38,0) -> 1 | AG38: =IF(AE38=1,AD38,0) -> 0 | AH38: =IF(AD38=0,"",IF(AD38=1,2,0))
A39: 3. Remediation activities are focused and MELC-based | AA39: TRUE | AB39: FALSE | AC39: =IF(AA39="","",IF(AA39=TRUE,1,0)) -> 1 | AD39: =IF(AB39="","",IF(AB39=TRUE,0.5,0)) -> 0 | AE39: =SUM(AC39:AD39) -> 1 | AF39: =IF(AE39=1,AC39,0) -> 1 | AG39: =IF(AE39=1,AD39,0) -> 0 | AH39: =IF(AD39=0,"",IF(AD39=1,2,0))
A40: 4. Progress of learners is regularly monitored | AA40: TRUE | AB40: FALSE | AC40: =IF(AA40="","",IF(AA40=TRUE,1,0)) -> 1 | AD40: =IF(AB40="","",IF(AB40=TRUE,0.5,0)) -> 0 | AE40: =SUM(AC40:AD40) -> 1 | AF40: =IF(AE40=1,AC40,0) -> 1 | AG40: =IF(AE40=1,AD40,0) -> 0 | AH40: =IF(AD40=0,"",IF(AD40=1,2,0))
AA41: FALSE | AB41: FALSE | AC41: =IF(AA41="","",IF(AA41=TRUE,1,0)) -> 0 | AD41: =IF(AB41="","",IF(AB41=TRUE,0.5,0)) -> 0 | AE41: =SUM(AC41:AD41) -> 0 | AF41: =IF(AE41=1,AC41,0) -> 0 | AG41: =IF(AE41=1,AD41,0) -> 0 | AH41: =IF(AD41=0,"",IF(AD41=1,2,0))
A42: E. DATA UTILIZATION (LAC & INSTRUCTIONAL ADJUSTMENT) | B42: =AF42 -> 4 | C42: =AG42 -> 0 | AC42: =IF(AA42="","",IF(AA42=TRUE,1,0)) | AD42: =IF(AB42="","",IF(AB42=TRUE,1,0)) | AF42: =SUM(AF37:AF41) -> 4 | AG42: =SUM(AG37:AG41) -> 0
A43: Indicator | B43: Yes | C43: No | D43: Remarks/Evidence | AC43: =IF(AA43="","",IF(AA43=TRUE,1,0)) | AD43: =IF(AB43="","",IF(AB43=TRUE,1,0))
A44: 1. Quarterly data review meetings are conducted | AA44: TRUE | AB44: FALSE | AC44: =IF(AA44="","",IF(AA44=TRUE,1,0)) -> 1 | AD44: =IF(AB44="","",IF(AB44=TRUE,0.5,0)) -> 0 | AE44: =SUM(AC44:AD44) -> 1 | AF44: =IF(AE44=1,AC44,0) -> 1 | AG44: =IF(AE44=1,AD44,0) -> 0 | AH44: =IF(AD44=0,"",IF(AD44=1,2,0))
A45: 2. LAC sessions include data discussion | AA45: FALSE | AB45: TRUE | AC45: =IF(AA45="","",IF(AA45=TRUE,1,0)) -> 0 | AD45: =IF(AB45="","",IF(AB45=TRUE,0.5,0)) -> 0.5 | AE45: =SUM(AC45:AD45) -> 0.5 | AF45: =IF(AE45=1,AC45,0) -> 0 | AG45: =IF(AE45=1,AD45,0) -> 0 | AH45: =IF(AD45=0,"",IF(AD45=1,2,0)) -> 0
A46: 3. Instruction is adjusted based on data | AA46: FALSE | AB46: TRUE | AC46: =IF(AA46="","",IF(AA46=TRUE,1,0)) -> 0 | AD46: =IF(AB46="","",IF(AB46=TRUE,0.5,0)) -> 0.5 | AE46: =SUM(AC46:AD46) -> 0.5 | AF46: =IF(AE46=1,AC46,0) -> 0 | AG46: =IF(AE46=1,AD46,0) -> 0 | AH46: =IF(AD46=0,"",IF(AD46=1,2,0)) -> 0
...

Sheet BAKILID ES
A5: Republic of the Philippines
A6: Department of Education
A8: SCHOOLS DIVISION OF MANDAUE CITY
A10: CURRICULUM, INSTRUCTION, AND ASSESSMENT MONITORING CHECKLIST
A11: School: | B11: BAKILID ELEMENTARY SCHOOL
A12: Quarter:
A13: Monitored by:
A14: A. CURRICULUM–INSTRUCTION–ASSESSMENT ALIGNMENT
A15: Indicator | B15: Yes | C15: No | D15: Remarks/Evidence
A16: 1. MELC mapping (Planned vs Taught vs Assessed) is conducted | AA16: FALSE | AB16: FALSE | AC16: =IF(AA16="","",IF(AA16=TRUE,1,0)) -> 0 | AD16: =IF(AB16="","",IF(AB16=TRUE,0.5,0)) -> 0 | AE16: =SUM(AC16:AD16) -> 0 | AF16: =IF(AE16=1,AC16,0) -> 0 | AG16: =IF(AE16=1,AD16,0) -> 0 | AH16: =IF(AD16=0,"",IF(AD16=1,2,0))
A17: 2. All MELCs are reflected in lesson plans | AA17: FALSE | AB17: FALSE | AC17: =IF(AA17="","",IF(AA17=TRUE,1,0)) -> 0 | AD17: =IF(AB17="","",IF(AB17=TRUE,0.5,0)) -> 0 | AE17: =SUM(AC17:AD17) -> 0 | AF17: =IF(AE17=1,AC17,0) -> 0 | AG17: =IF(AE17=1,AD17,0) -> 0 | AH17: =IF(AD17=0,"",IF(AD17=1,2,0))
A18: 3. Assessments are aligned with taught MELCs | AA18: FALSE | AB18: FALSE | AC18: =IF(AA18="","",IF(AA18=TRUE,1,0)) -> 0 | AD18: =IF(AB18="","",IF(AB18=TRUE,0.5,0)) -> 0 | AE18: =SUM(AC18:AD18) -> 0 | AF18: =IF(AE18=1,AC18,0) -> 0 | AG18: =IF(AE18=1,AD18,0) -> 0 | AH18: =IF(AD18=0,"",IF(AD18=1,2,0))
A19: 4. High-frequency NAT MELCs are prioritized | AA19: FALSE | AB19: FALSE | AC19: =IF(AA19="","",IF(AA19=TRUE,1,0)) -> 0 | AD19: =IF(AB19="","",IF(AB19=TRUE,0.5,0)) -> 0 | AE19: =SUM(AC19:AD19) -> 0 | AF19: =IF(AE19=1,AC19,0) -> 0 | AG19: =IF(AE19=1,AD19,0) -> 0 | AH19: =IF(AD19=0,"",IF(AD19=1,2,0))
AA20: FALSE | AB20: FALSE | AC20: =IF(AA20="","",IF(AA20=TRUE,1,0)) -> 0 | AD20: =IF(AB20="","",IF(AB20=TRUE,0.5,0)) -> 0 | AE20: =SUM(AC20:AD20) -> 0 | AF20: =IF(AE20=1,AC20,0) -> 0 | AG20: =IF(AE20=1,AD20,0) -> 0 | AH20: =IF(AD20=0,"",IF(AD20=1,2,0))
A21: B. ASSESSMENT QUALITY (HOTS-BASED) | B21: =AF21 -> 0 | C21: =AG21 -> 0 | AC21: =IF(AA21="","",IF(AA21=TRUE,1,0)) | AD21: =IF(AB21="","",IF(AB21=TRUE,1,0)) | AF21: =SUM(AF16:AF20) -> 0 | AG21: =SUM(AG16:AG20) -> 0
A22: Indicator | B22: Yes | C22: No | D22: Remarks/Evidence | AC22: =IF(AA22="","",IF(AA22=TRUE,1,0)) | AD22: =IF(AB22="","",IF(AB22=TRUE,1,0))
A23: 1. Classroom tests include 40–50% HOTS items | AA23: FALSE | AB23: FALSE | AC23: =IF(AA23="","",IF(AA23=TRUE,1,0)) -> 0 | AD23: =IF(AB23="","",IF(AB23=TRUE,0.5,0)) -> 0 | AE23: =SUM(AC23:AD23) -> 0 | AF23: =IF(AE23=1,AC23,0) -> 0 | AG23: =IF(AE23=1,AD23,0) -> 0 | AH23: =IF(AD23=0,"",IF(AD23=1,2,0))
A24: 2. Test items reflect application, analysis, interpretation | AA24: FALSE | AB24: FALSE | AC24: =IF(AA24="","",IF(AA24=TRUE,1,0)) -> 0 | AD24: =IF(AB24="","",IF(AB24=TRUE,0.5,0)) -> 0 | AE24: =SUM(AC24:AD24) -> 0 | AF24: =IF(AE24=1,AC24,0) -> 0 | AG24: =IF(AE24=1,AD24,0) -> 0 | AH24: =IF(AD24=0,"",IF(AD24=1,2,0))
A25: 3. NAT-like test items are used | AA25: FALSE | AB25: FALSE | AC25: =IF(AA25="","",IF(AA25=TRUE,1,0)) -> 0 | AD25: =IF(AB25="","",IF(AB25=TRUE,0.5,0)) -> 0 | AE25: =SUM(AC25:AD25) -> 0 | AF25: =IF(AE25=1,AC25,0) -> 0 | AG25: =IF(AE25=1,AD25,0) -> 0 | AH25: =IF(AD25=0,"",IF(AD25=1,2,0))
A26: 4. Item analysis is conducted after assessments | AA26: FALSE | AB26: FALSE | AC26: =IF(AA26="","",IF(AA26=TRUE,1,0)) -> 0 | AD26: =IF(AB26="","",IF(AB26=TRUE,0.5,0)) -> 0 | AE26: =SUM(AC26:AD26) -> 0 | AF26: =IF(AE26=1,AC26,0) -> 0 | AG26: =IF(AE26=1,AD26,0) -> 0 | AH26: =IF(AD26=0,"",IF(AD26=1,2,0))
AA27: FALSE | AB27: FALSE | AC27: =IF(AA27="","",IF(AA27=TRUE,1,0)) -> 0 | AD27: =IF(AB27="","",IF(AB27=TRUE,0.5,0)) -> 0 | AE27: =SUM(AC27:AD27) -> 0 | AF27: =IF(AE27=1,AC27,0) -> 0 | AG27: =IF(AE27=1,AD27,0) -> 0 | AH27: =IF(AD27=0,"",IF(AD27=1,2,0))
A28: C. READING ACROSS LEARNING AREAS | B28: =AF28 -> 0 | C28: =AG28 -> 0 | AC28: =IF(AA28="","",IF(AA28=TRUE,1,0)) | AD28: =IF(AB28="","",IF(AB28=TRUE,1,0)) | AF28: =SUM(AF23:AF27) -> 0 | AG28: =SUM(AG23:AG27) -> 0
A29: Indicator | B29: Yes | C29: No | D29: Remarks/Evidence | AC29: =IF(AA29="","",IF(AA29=TRUE,1,0)) | AD29: =IF(AB29="","",IF(AB29=TRUE,1,0))
A30: 1. Reading strategies are integrated in all subjects | AA30: FALSE | AB30: FALSE | AC30: =IF(AA30="","",IF(AA30=TRUE,1,0)) -> 0 | AD30: =IF(AB30="","",IF(AB30=TRUE,0.5,0)) -> 0 | AE30: =SUM(AC30:AD30) -> 0 | AF30: =IF(AE30=1,AC30,0) -> 0 | AG30: =IF(AE30=1,AD30,0) -> 0 | AH30: =IF(AD30=0,"",IF(AD30=1,2,0))
A31: 2. Vocabulary is pre-taught before lessons | AA31: FALSE | AB31: FALSE | AC31: =IF(AA31="","",IF(AA31=TRUE,1,0)) -> 0 | AD31: =IF(AB31="","",IF(AB31=TRUE,0.5,0)) -> 0 | AE31: =SUM(AC31:AD31) -> 0 | AF31: =IF(AE31=1,AC31,0) -> 0 | AG31: =IF(AE31=1,AD31,0) -> 0 | AH31: =IF(AD31=0,"",IF(AD31=1,2,0))
A32: 3. Learners explain answers in words | AA32: FALSE | AB32: FALSE | AC32: =IF(AA32="","",IF(AA32=TRUE,1,0)) -> 0 | AD32: =IF(AB32="","",IF(AB32=TRUE,0.5,0)) -> 0 | AE32: =SUM(AC32:AD32) -> 0 | AF32: =IF(AE32=1,AC32,0) -> 0 | AG32: =IF(AE32=1,AD32,0) -> 0 | AH32: =IF(AD32=0,"",IF(AD32=1,2,0))
A33: 4. Learners justify solutions/answers | AA33: FALSE | AB33: FALSE | AC33: =IF(AA33="","",IF(AA33=TRUE,1,0)) -> 0 | AD33: =IF(AB33="","",IF(AB33=TRUE,0.5,0)) -> 0 | AE33: =SUM(AC33:AD33) -> 0 | AF33: =IF(AE33=1,AC33,0) -> 0 | AG33: =IF(AE33=1,AD33,0) -> 0 | AH33: =IF(AD33=0,"",IF(AD33=1,2,0))
AA34: FALSE | AB34: FALSE | AC34: =IF(AA34="","",IF(AA34=TRUE,1,0)) -> 0 | AD34: =IF(AB34="","",IF(AB34=TRUE,0.5,0)) -> 0 | AE34: =SUM(AC34:AD34) -> 0 | AF34: =IF(AE34=1,AC34,0) -> 0 | AG34: =IF(AE34=1,AD34,0) -> 0 | AH34: =IF(AD34=0,"",IF(AD34=1,2,0))
A35: D. TARGETED REMEDIATION | B35: =AF35 -> 0 | C35: =AG35 -> 0 | AC35: =IF(AA35="","",IF(AA35=TRUE,1,0)) | AD35: =IF(AB35="","",IF(AB35=TRUE,1,0)) | AF35: =SUM(AF30:AF34) -> 0 | AG35: =SUM(AG30:AG34) -> 0
A36: Indicator | B36: Yes | C36: No | D36: Remarks/Evidence | AC36: =IF(AA36="","",IF(AA36=TRUE,1,0)) | AD36: =IF(AB36="","",IF(AB36=TRUE,1,0))
A37: 1. Item analysis identifies specific MELC gaps | AA37: FALSE | AB37: FALSE | AC37: =IF(AA37="","",IF(AA37=TRUE,1,0)) -> 0 | AD37: =IF(AB37="","",IF(AB37=TRUE,0.5,0)) -> 0 | AE37: =SUM(AC37:AD37) -> 0 | AF37: =IF(AE37=1,AC37,0) -> 0 | AG37: =IF(AE37=1,AD37,0) -> 0 | AH37: =IF(AD37=0,"",IF(AD37=1,2,0))
A38: 2. Learners are grouped based on skill gaps | AA38: FALSE | AB38: FALSE | AC38: =IF(AA38="","",IF(AA38=TRUE,1,0)) -> 0 | AD38: =IF(AB38="","",IF(AB38=TRUE,0.5,0)) -> 0 | AE38: =SUM(AC38:AD38) -> 0 | AF38: =IF(AE38=1,AC38,0) -> 0 | AG38: =IF(AE38=1,AD38,0) -> 0 | AH38: =IF(AD38=0,"",IF(AD38=1,2,0))
A39: 3. Remediation activities are focused and MELC-based | AA39: FALSE | AB39: FALSE | AC39: =IF(AA39="","",IF(AA39=TRUE,1,0)) -> 0 | AD39: =IF(AB39="","",IF(AB39=TRUE,0.5,0)) -> 0 | AE39: =SUM(AC39:AD39) -> 0 | AF39: =IF(AE39=1,AC39,0) -> 0 | AG39: =IF(AE39=1,AD39,0) -> 0 | AH39: =IF(AD39=0,"",IF(AD39=1,2,0))
A40: 4. Progress of learners is regularly monitored | AA40: FALSE | AB40: FALSE | AC40: =IF(AA40="","",IF(AA40=TRUE,1,0)) -> 0 | AD40: =IF(AB40="","",IF(AB40=TRUE,0.5,0)) -> 0 | AE40: =SUM(AC40:AD40) -> 0 | AF40: =IF(AE40=1,AC40,0) -> 0 | AG40: =IF(AE40=1,AD40,0) -> 0 | AH40: =IF(AD40=0,"",IF(AD40=1,2,0))
AA41: FALSE | AB41: FALSE | AC41: =IF(AA41="","",IF(AA41=TRUE,1,0)) -> 0 | AD41: =IF(AB41="","",IF(AB41=TRUE,0.5,0)) -> 0 | AE41: =SUM(AC41:AD41) -> 0 | AF41: =IF(AE41=1,AC41,0) -> 0 | AG41: =IF(AE41=1,AD41,0) -> 0 | AH41: =IF(AD41=0,"",IF(AD41=1,2,0))
A42: E. DATA UTILIZATION (LAC & INSTRUCTIONAL ADJUSTMENT) | B42: =AF42 -> 0 | C42: =AG42 -> 0 | AC42: =IF(AA42="","",IF(AA42=TRUE,1,0)) | AD42: =IF(AB42="","",IF(AB42=TRUE,1,0)) | AF42: =SUM(AF37:AF41) -> 0 | AG42: =SUM(AG37:AG41) -> 0
A43: Indicator | B43: Yes | C43: No | D43: Remarks/Evidence | AC43: =IF(AA43="","",IF(AA43=TRUE,1,0)) | AD43: =IF(AB43="","",IF(AB43=TRUE,1,0))
A44: 1. Quarterly data review meetings are conducted | AA44: FALSE | AB44: FALSE | AC44: =IF(AA44="","",IF(AA44=TRUE,1,0)) -> 0 | AD44: =IF(AB44="","",IF(AB44=TRUE,0.5,0)) -> 0 | AE44: =SUM(AC44:AD44) -> 0 | AF44: =IF(AE44=1,AC44,0) -> 0 | AG44: =IF(AE44=1,AD44,0) -> 0 | AH44: =IF(AD44=0,"",IF(AD44=1,2,0))
A45: 2. LAC sessions include data discussion | AA45: FALSE | AB45: FALSE | AC45: =IF(AA45="","",IF(AA45=TRUE,1,0)) -> 0 | AD45: =IF(AB45="","",IF(AB45=TRUE,0.5,0)) -> 0 | AE45: =SUM(AC45:AD45) -> 0 | AF45: =IF(AE45=1,AC45,0) -> 0 | AG45: =IF(AE45=1,AD45,0) -> 0 | AH45: =IF(AD45=0,"",IF(AD45=1,2,0))
A46: 3. Instruction is adjusted based on data | AA46: FALSE | AB46: FALSE | AC46: =IF(AA46="","",IF(AA46=TRUE,1,0)) -> 0 | AD46: =IF(AB46="","",IF(AB46=TRUE,0.5,0)) -> 0 | AE46: =SUM(AC46:AD46) -> 0 | AF46: =IF(AE46=1,AC46,0) -> 0 | AG46: =IF(AE46=1,AD46,0) -> 0 | AH46: =IF(AD46=0,"",IF(AD46=1,2,0))
...

Sheet TINGUB ES
A5: Republic of the Philippines
A6: Department of Education
A8: SCHOOLS DIVISION OF MANDAUE CITY
A10: CURRICULUM, INSTRUCTION, AND ASSESSMENT MONITORING CHECKLIST
A11: School: | B11: TINGUB ELEMENTARY SCHOOL
A12: Quarter:
A13: Monitored by:
A14: A. CURRICULUM–INSTRUCTION–ASSESSMENT ALIGNMENT
A15: Indicator | B15: Yes | C15: No | D15: Remarks/Evidence
A16: 1. MELC mapping (Planned vs Taught vs Assessed) is conducted | AA16: FALSE | AB16: FALSE | AC16: =IF(AA16="","",IF(AA16=TRUE,1,0)) -> 0 | AD16: =IF(AB16="","",IF(AB16=TRUE,0.5,0)) -> 0 | AE16: =SUM(AC16:AD16) -> 0 | AF16: =IF(AE16=1,AC16,0) -> 0 | AG16: =IF(AE16=1,AD16,0) -> 0 | AH16: =IF(AD16=0,"",IF(AD16=1,2,0))
A17: 2. All MELCs are reflected in lesson plans | AA17: FALSE | AB17: FALSE | AC17: =IF(AA17="","",IF(AA17=TRUE,1,0)) -> 0 | AD17: =IF(AB17="","",IF(AB17=TRUE,0.5,0)) -> 0 | AE17: =SUM(AC17:AD17) -> 0 | AF17: =IF(AE17=1,AC17,0) -> 0 | AG17: =IF(AE17=1,AD17,0) -> 0 | AH17: =IF(AD17=0,"",IF(AD17=1,2,0))
A18: 3. Assessments are aligned with taught MELCs | AA18: FALSE | AB18: FALSE | AC18: =IF(AA18="","",IF(AA18=TRUE,1,0)) -> 0 | AD18: =IF(AB18="","",IF(AB18=TRUE,0.5,0)) -> 0 | AE18: =SUM(AC18:AD18) -> 0 | AF18: =IF(AE18=1,AC18,0) -> 0 | AG18: =IF(AE18=1,AD18,0) -> 0 | AH18: =IF(AD18=0,"",IF(AD18=1,2,0))
A19: 4. High-frequency NAT MELCs are prioritized | AA19: FALSE | AB19: FALSE | AC19: =IF(AA19="","",IF(AA19=TRUE,1,0)) -> 0 | AD19: =IF(AB19="","",IF(AB19=TRUE,0.5,0)) -> 0 | AE19: =SUM(AC19:AD19) -> 0 | AF19: =IF(AE19=1,AC19,0) -> 0 | AG19: =IF(AE19=1,AD19,0) -> 0 | AH19: =IF(AD19=0,"",IF(AD19=1,2,0))
AA20: FALSE | AB20: FALSE | AC20: =IF(AA20="","",IF(AA20=TRUE,1,0)) -> 0 | AD20: =IF(AB20="","",IF(AB20=TRUE,0.5,0)) -> 0 | AE20: =SUM(AC20:AD20) -> 0 | AF20: =IF(AE20=1,AC20,0) -> 0 | AG20: =IF(AE20=1,AD20,0) -> 0 | AH20: =IF(AD20=0,"",IF(AD20=1,2,0))
A21: B. ASSESSMENT QUALITY (HOTS-BASED) | B21: =AF21 -> 0 | C21: =AG21 -> 0 | AC21: =IF(AA21="","",IF(AA21=TRUE,1,0)) | AD21: =IF(AB21="","",IF(AB21=TRUE,1,0)) | AF21: =SUM(AF16:AF20) -> 0 | AG21: =SUM(AG16:AG20) -> 0
A22: Indicator | B22: Yes | C22: No | D22: Remarks/Evidence | AC22: =IF(AA22="","",IF(AA22=TRUE,1,0)) | AD22: =IF(AB22="","",IF(AB22=TRUE,1,0))
A23: 1. Classroom tests include 40–50% HOTS items | AA23: FALSE | AB23: FALSE | AC23: =IF(AA23="","",IF(AA23=TRUE,1,0)) -> 0 | AD23: =IF(AB23="","",IF(AB23=TRUE,0.5,0)) -> 0 | AE23: =SUM(AC23:AD23) -> 0 | AF23: =IF(AE23=1,AC23,0) -> 0 | AG23: =IF(AE23=1,AD23,0) -> 0 | AH23: =IF(AD23=0,"",IF(AD23=1,2,0))
A24: 2. Test items reflect application, analysis, interpretation | AA24: FALSE | AB24: FALSE | AC24: =IF(AA24="","",IF(AA24=TRUE,1,0)) -> 0 | AD24: =IF(AB24="","",IF(AB24=TRUE,0.5,0)) -> 0 | AE24: =SUM(AC24:AD24) -> 0 | AF24: =IF(AE24=1,AC24,0) -> 0 | AG24: =IF(AE24=1,AD24,0) -> 0 | AH24: =IF(AD24=0,"",IF(AD24=1,2,0))
A25: 3. NAT-like test items are used | AA25: FALSE | AB25: FALSE | AC25: =IF(AA25="","",IF(AA25=TRUE,1,0)) -> 0 | AD25: =IF(AB25="","",IF(AB25=TRUE,0.5,0)) -> 0 | AE25: =SUM(AC25:AD25) -> 0 | AF25: =IF(AE25=1,AC25,0) -> 0 | AG25: =IF(AE25=1,AD25,0) -> 0 | AH25: =IF(AD25=0,"",IF(AD25=1,2,0))
A26: 4. Item analysis is conducted after assessments | AA26: FALSE | AB26: FALSE | AC26: =IF(AA26="","",IF(AA26=TRUE,1,0)) -> 0 | AD26: =IF(AB26="","",IF(AB26=TRUE,0.5,0)) -> 0 | AE26: =SUM(AC26:AD26) -> 0 | AF26: =IF(AE26=1,AC26,0) -> 0 | AG26: =IF(AE26=1,AD26,0) -> 0 | AH26: =IF(AD26=0,"",IF(AD26=1,2,0))
AA27: FALSE | AB27: FALSE | AC27: =IF(AA27="","",IF(AA27=TRUE,1,0)) -> 0 | AD27: =IF(AB27="","",IF(AB27=TRUE,0.5,0)) -> 0 | AE27: =SUM(AC27:AD27) -> 0 | AF27: =IF(AE27=1,AC27,0) -> 0 | AG27: =IF(AE27=1,AD27,0) -> 0 | AH27: =IF(AD27=0,"",IF(AD27=1,2,0))
A28: C. READING ACROSS LEARNING AREAS | B28: =AF28 -> 0 | C28: =AG28 -> 0 | AC28: =IF(AA28="","",IF(AA28=TRUE,1,0)) | AD28: =IF(AB28="","",IF(AB28=TRUE,1,0)) | AF28: =SUM(AF23:AF27) -> 0 | AG28: =SUM(AG23:AG27) -> 0
A29: Indicator | B29: Yes | C29: No | D29: Remarks/Evidence | AC29: =IF(AA29="","",IF(AA29=TRUE,1,0)) | AD29: =IF(AB29="","",IF(AB29=TRUE,1,0))
A30: 1. Reading strategies are integrated in all subjects | AA30: FALSE | AB30: FALSE | AC30: =IF(AA30="","",IF(AA30=TRUE,1,0)) -> 0 | AD30: =IF(AB30="","",IF(AB30=TRUE,0.5,0)) -> 0 | AE30: =SUM(AC30:AD30) -> 0 | AF30: =IF(AE30=1,AC30,0) -> 0 | AG30: =IF(AE30=1,AD30,0) -> 0 | AH30: =IF(AD30=0,"",IF(AD30=1,2,0))
A31: 2. Vocabulary is pre-taught before lessons | AA31: FALSE | AB31: FALSE | AC31: =IF(AA31="","",IF(AA31=TRUE,1,0)) -> 0 | AD31: =IF(AB31="","",IF(AB31=TRUE,0.5,0)) -> 0 | AE31: =SUM(AC31:AD31) -> 0 | AF31: =IF(AE31=1,AC31,0) -> 0 | AG31: =IF(AE31=1,AD31,0) -> 0 | AH31: =IF(AD31=0,"",IF(AD31=1,2,0))
A32: 3. Learners explain answers in words | AA32: FALSE | AB32: FALSE | AC32: =IF(AA32="","",IF(AA32=TRUE,1,0)) -> 0 | AD32: =IF(AB32="","",IF(AB32=TRUE,0.5,0)) -> 0 | AE32: =SUM(AC32:AD32) -> 0 | AF32: =IF(AE32=1,AC32,0) -> 0 | AG32: =IF(AE32=1,AD32,0) -> 0 | AH32: =IF(AD32=0,"",IF(AD32=1,2,0))
A33: 4. Learners justify solutions/answers | AA33: FALSE | AB33: FALSE | AC33: =IF(AA33="","",IF(AA33=TRUE,1,0)) -> 0 | AD33: =IF(AB33="","",IF(AB33=TRUE,0.5,0)) -> 0 | AE33: =SUM(AC33:AD33) -> 0 | AF33: =IF(AE33=1,AC33,0) -> 0 | AG33: =IF(AE33=1,AD33,0) -> 0 | AH33: =IF(AD33=0,"",IF(AD33=1,2,0))
AA34: FALSE | AB34: FALSE | AC34: =IF(AA34="","",IF(AA34=TRUE,1,0)) -> 0 | AD34: =IF(AB34="","",IF(AB34=TRUE,0.5,0)) -> 0 | AE34: =SUM(AC34:AD34) -> 0 | AF34: =IF(AE34=1,AC34,0) -> 0 | AG34: =IF(AE34=1,AD34,0) -> 0 | AH34: =IF(AD34=0,"",IF(AD34=1,2,0))
A35: D. TARGETED REMEDIATION | B35: =AF35 -> 0 | C35: =AG35 -> 0 | AC35: =IF(AA35="","",IF(AA35=TRUE,1,0)) | AD35: =IF(AB35="","",IF(AB35=TRUE,1,0)) | AF35: =SUM(AF30:AF34) -> 0 | AG35: =SUM(AG30:AG34) -> 0
A36: Indicator | B36: Yes | C36: No | D36: Remarks/Evidence | AC36: =IF(AA36="","",IF(AA36=TRUE,1,0)) | AD36: =IF(AB36="","",IF(AB36=TRUE,1,0))
A37: 1. Item analysis identifies specific MELC gaps | AA37: FALSE | AB37: FALSE | AC37: =IF(AA37="","",IF(AA37=TRUE,1,0)) -> 0 | AD37: =IF(AB37="","",IF(AB37=TRUE,0.5,0)) -> 0 | AE37: =SUM(AC37:AD37) -> 0 | AF37: =IF(AE37=1,AC37,0) -> 0 | AG37: =IF(AE37=1,AD37,0) -> 0 | AH37: =IF(AD37=0,"",IF(AD37=1,2,0))
A38: 2. Learners are grouped based on skill gaps | AA38: FALSE | AB38: FALSE | AC38: =IF(AA38="","",IF(AA38=TRUE,1,0)) -> 0 | AD38: =IF(AB38="","",IF(AB38=TRUE,0.5,0)) -> 0 | AE38: =SUM(AC38:AD38) -> 0 | AF38: =IF(AE38=1,AC38,0) -> 0 | AG38: =IF(AE38=1,AD38,0) -> 0 | AH38: =IF(AD38=0,"",IF(AD38=1,2,0))
A39: 3. Remediation activities are focused and MELC-based | AA39: FALSE | AB39: FALSE | AC39: =IF(AA39="","",IF(AA39=TRUE,1,0)) -> 0 | AD39: =IF(AB39="","",IF(AB39=TRUE,0.5,0)) -> 0 | AE39: =SUM(AC39:AD39) -> 0 | AF39: =IF(AE39=1,AC39,0) -> 0 | AG39: =IF(AE39=1,AD39,0) -> 0 | AH39: =IF(AD39=0,"",IF(AD39=1,2,0))
A40: 4. Progress of learners is regularly monitored | AA40: FALSE | AB40: FALSE | AC40: =IF(AA40="","",IF(AA40=TRUE,1,0)) -> 0 | AD40: =IF(AB40="","",IF(AB40=TRUE,0.5,0)) -> 0 | AE40: =SUM(AC40:AD40) -> 0 | AF40: =IF(AE40=1,AC40,0) -> 0 | AG40: =IF(AE40=1,AD40,0) -> 0 | AH40: =IF(AD40=0,"",IF(AD40=1,2,0))
AA41: FALSE | AB41: FALSE | AC41: =IF(AA41="","",IF(AA41=TRUE,1,0)) -> 0 | AD41: =IF(AB41="","",IF(AB41=TRUE,0.5,0)) -> 0 | AE41: =SUM(AC41:AD41) -> 0 | AF41: =IF(AE41=1,AC41,0) -> 0 | AG41: =IF(AE41=1,AD41,0) -> 0 | AH41: =IF(AD41=0,"",IF(AD41=1,2,0))
A42: E. DATA UTILIZATION (LAC & INSTRUCTIONAL ADJUSTMENT) | B42: =AF42 -> 0 | C42: =AG42 -> 0 | AC42: =IF(AA42="","",IF(AA42=TRUE,1,0)) | AD42: =IF(AB42="","",IF(AB42=TRUE,1,0)) | AF42: =SUM(AF37:AF41) -> 0 | AG42: =SUM(AG37:AG41) -> 0
A43: Indicator | B43: Yes | C43: No | D43: Remarks/Evidence | AC43: =IF(AA43="","",IF(AA43=TRUE,1,0)) | AD43: =IF(AB43="","",IF(AB43=TRUE,1,0))
A44: 1. Quarterly data review meetings are conducted | AA44: FALSE | AB44: FALSE | AC44: =IF(AA44="","",IF(AA44=TRUE,1,0)) -> 0 | AD44: =IF(AB44="","",IF(AB44=TRUE,0.5,0)) -> 0 | AE44: =SUM(AC44:AD44) -> 0 | AF44: =IF(AE44=1,AC44,0) -> 0 | AG44: =IF(AE44=1,AD44,0) -> 0 | AH44: =IF(AD44=0,"",IF(AD44=1,2,0))
A45: 2. LAC sessions include data discussion | AA45: FALSE | AB45: FALSE | AC45: =IF(AA45="","",IF(AA45=TRUE,1,0)) -> 0 | AD45: =IF(AB45="","",IF(AB45=TRUE,0.5,0)) -> 0 | AE45: =SUM(AC45:AD45) -> 0 | AF45: =IF(AE45=1,AC45,0) -> 0 | AG45: =IF(AE45=1,AD45,0) -> 0 | AH45: =IF(AD45=0,"",IF(AD45=1,2,0))
A46: 3. Instruction is adjusted based on data | AA46: FALSE | AB46: FALSE | AC46: =IF(AA46="","",IF(AA46=TRUE,1,0)) -> 0 | AD46: =IF(AB46="","",IF(AB46=TRUE,0.5,0)) -> 0 | AE46: =SUM(AC46:AD46) -> 0 | AF46: =IF(AE46=1,AC46,0) -> 0 | AG46: =IF(AE46=1,AD46,0) -> 0 | AH46: =IF(AD46=0,"",IF(AD46=1,2,0))
...

Sheet SUMMARY
A5: Republic of the Philippines
A6: Department of Education
A8: SCHOOLS DIVISION OF MANDAUE CITY
A10: CURRICULUM, INSTRUCTION, AND ASSESSMENT MONITORING CHECKLIST
A12: SCHOOL | B12: =IF('MAGUIKAY ES'!$A$14="","",'MAGUIKAY ES'!$A$14) -> A. CURRICULUM–INSTRUCTION–ASSESSMENT ALIGNMENT | G12: Weighted Mean | H12: Description | I12: =IF('MAGUIKAY ES'!$A$21="","",'MAGUIKAY ES'!$A$21) -> B. ASSESSMENT QUALITY (HOTS-BASED) | N12: Weighted Mean | O12: Description | P12: =IF('MAGUIKAY ES'!$A$28="","",'MAGUIKAY ES'!$A$28) -> C. READING ACROSS LEARNING AREAS | U12: Weighted Mean | V12: Description | W12: =IF('MAGUIKAY ES'!$A$35="","",'MAGUIKAY ES'!$A$35) -> D. TARGETED REMEDIATION | AB12: Weighted Mean | AC12: Description | AD12: =IF('MAGUIKAY ES'!$A$42="","",'MAGUIKAY ES'!$A$42) -> E. DATA UTILIZATION (LAC & INSTRUCTIONAL ADJUSTMENT) | AI12: Weighted Mean | AJ12: Description | AK12: =IF('MAGUIKAY ES'!$A$49="","",'MAGUIKAY ES'!$A$49) -> F. LEARNING RESOURCE (LR) QUALITY & UTILIZATION | AP12: Weighted Mean | AQ12: Description | AR12: =IF('MAGUIKAY ES'!$A$56="","",'MAGUIKAY ES'!$A$56) -> G. TECHNICAL ASSISTANCE (TA) IMPLEMENTATION | AW12: Weighted Mean | AX12: Description | AY12: =IF('MAGUIKAY ES'!$A$63="","",'MAGUIKAY ES'!$A$63) -> H. INSTRUCTIONAL LEADERSHIP & MONITORING | BD12: Weighted Mean | BE12: Description | BF12: =IF('MAGUIKAY ES'!$A$70="","",'MAGUIKAY ES'!$A$70) -> I. OVERALL DATA-TO-ACTION CYCLE | BK12: Weighted Mean | BL12: Description
B13: =IF('MAGUIKAY ES'!$A$16<>"", "A.1.1", "") -> A.1.1 | C13: =IF('MAGUIKAY ES'!$A$17<>"", "A.1.2", "") -> A.1.2 | D13: =IF('MAGUIKAY ES'!$A$18<>"", "A.1.3", "") -> A.1.3 | E13: =IF('MAGUIKAY ES'!$A$19<>"", "A.1.4", "") -> A.1.4 | I13: =IF('MAGUIKAY ES'!$A$23<>"", "B.1.1", "") -> B.1.1 | J13: =IF('MAGUIKAY ES'!$A$24<>"", "B.1.2", "") -> B.1.2 | K13: =IF('MAGUIKAY ES'!$A$25<>"", "B.1.3", "") -> B.1.3 | L13: =IF('MAGUIKAY ES'!$A$26<>"", "B.1.4", "") -> B.1.4 | P13: =IF('MAGUIKAY ES'!$A$30<>"", "C.1.1", "") -> C.1.1 | Q13: =IF('MAGUIKAY ES'!$A$31<>"", "C.1.2", "") -> C.1.2 | R13: =IF('MAGUIKAY ES'!$A$32<>"", "C.1.3", "") -> C.1.3 | S13: =IF('MAGUIKAY ES'!$A$33<>"", "C.1.4", "") -> C.1.4 | W13: =IF('MAGUIKAY ES'!$A$37<>"", "D.1.1", "") -> D.1.1 | X13: =IF('MAGUIKAY ES'!$A$38<>"", "D.1.2", "") -> D.1.2 | Y13: =IF('MAGUIKAY ES'!$A$39<>"", "D.1.3", "") -> D.1.3 | Z13: =IF('MAGUIKAY ES'!$A$40<>"", "D.1.4", "") -> D.1.4 | AD13: =IF('MAGUIKAY ES'!$A$44<>"", "E.1.1", "") -> E.1.1 | AE13: =IF('MAGUIKAY ES'!$A$45<>"", "E.1.2", "") -> E.1.2 | AF13: =IF('MAGUIKAY ES'!$A$46<>"", "E.1.3", "") -> E.1.3 | AG13: =IF('MAGUIKAY ES'!$A$47<>"", "E.1.4", "") -> E.1.4 | AK13: =IF('MAGUIKAY ES'!$A$51<>"", "F.1.1", "") -> F.1.1 | AL13: =IF('MAGUIKAY ES'!$A$52<>"", "F.1.2", "") -> F.1.2 | AM13: =IF('MAGUIKAY ES'!$A$53<>"", "F.1.3", "") -> F.1.3 | AN13: =IF('MAGUIKAY ES'!$A$54<>"", "F.1.4", "") -> F.1.4 | AO13: =IF('MAGUIKAY ES'!$A$55<>"", "F.1.5", "") -> F.1.5 | AR13: =IF('MAGUIKAY ES'!$A$58<>"", "G.1.1", "") -> G.1.1 | AS13: =IF('MAGUIKAY ES'!$A$59<>"", "G.1.2", "") -> G.1.2 | AT13: =IF('MAGUIKAY ES'!$A$60<>"", "G.1.3", "") -> G.1.3 | AU13: =IF('MAGUIKAY ES'!$A$61<>"", "G.1.4", "") -> G.1.4 | AV13: =IF('MAGUIKAY ES'!$A$62<>"", "G.1.5", "") | AY13: =IF('MAGUIKAY ES'!$A$65<>"", "H.1.1", "") -> H.1.1 | AZ13: =IF('MAGUIKAY ES'!$A$66<>"", "H.1.2", "") -> H.1.2 | BA13: =IF('MAGUIKAY ES'!$A$67<>"", "H.1.3", "") -> H.1.3 | BB13: =IF('MAGUIKAY ES'!$A$68<>"", "H.1.4", "") -> H.1.4 | BC13: =IF('MAGUIKAY ES'!$A$69<>"", "H.1.5", "") -> H.1.5 | BF13: =IF('MAGUIKAY ES'!$A$72<>"", "I.1.1", "") -> I.1.1 | BG13: =IF('MAGUIKAY ES'!$A$73<>"", "I.1.2", "") -> I.1.2 | BH13: =IF('MAGUIKAY ES'!$A$74<>"", "I.1.3", "") -> I.1.3 | BI13: =IF('MAGUIKAY ES'!$A$75<>"", "I.1.4", "") -> I.1.4 | BJ13: =IF('MAGUIKAY ES'!$A$76<>"", "I.1.5", "")
A14: =IF('MAGUIKAY ES'!$B$11="","",'MAGUIKAY ES'!$B$11) -> MAGUIKAY ELEMENTARY SCHOOL | B14: =IF('MAGUIKAY ES'!$AE$16=1,1,IF('MAGUIKAY ES'!$AE$16=0.5,2,"")) | C14: =IF('MAGUIKAY ES'!$AE$17=1,1,IF('MAGUIKAY ES'!$AE$17=0.5,2,"")) | D14: =IF('MAGUIKAY ES'!$AE$18=1,1,IF('MAGUIKAY ES'!$AE$18=0.5,2,"")) | E14: =IF('MAGUIKAY ES'!$AE$19=1,1,IF('MAGUIKAY ES'!$AE$19=0.5,2,"")) | G14: =IFERROR(ROUND(AVERAGE(B14:F14),2), "") | H14: =IF(G14="","",VLOOKUP(G14,$CH$14:$CK$17,3)) | I14: =IF('MAGUIKAY ES'!$AE$23=1,1,IF('MAGUIKAY ES'!$AE$23=0.5,2,"")) | J14: =IF('MAGUIKAY ES'!$AE$24=1,1,IF('MAGUIKAY ES'!$AE$24=0.5,2,"")) | K14: =IF('MAGUIKAY ES'!$AE$25=1,1,IF('MAGUIKAY ES'!$AE$25=0.5,2,"")) | L14: =IF('MAGUIKAY ES'!$AE$26=1,1,IF('MAGUIKAY ES'!$AE$26=0.5,2,"")) | N14: =IFERROR(ROUND(AVERAGE(I14:M14),2), "") | O14: =IF(N14="","",VLOOKUP(N14,$CH$14:$CK$17,3)) | P14: =IF('MAGUIKAY ES'!$AE$30=1,1,IF('MAGUIKAY ES'!$AE$30=0.5,2,"")) | Q14: =IF('MAGUIKAY ES'!$AE$31=1,1,IF('MAGUIKAY ES'!$AE$31=0.5,2,"")) | R14: =IF('MAGUIKAY ES'!$AE$32=1,1,IF('MAGUIKAY ES'!$AE$32=0.5,2,"")) | S14: =IF('MAGUIKAY ES'!$AE$33=1,1,IF('MAGUIKAY ES'!$AE$33=0.5,2,"")) | U14: =IFERROR(ROUND(AVERAGE(P14:T14),2), "") | V14: =IF(U14="","",VLOOKUP(U14,$CH$14:$CK$17,3)) | W14: =IF('MAGUIKAY ES'!$AE$37=1,1,IF('MAGUIKAY ES'!$AE$37=0.5,2,"")) | X14: =IF('MAGUIKAY ES'!$AE$38=1,1,IF('MAGUIKAY ES'!$AE$38=0.5,2,"")) | Y14: =IF('MAGUIKAY ES'!$AE$39=1,1,IF('MAGUIKAY ES'!$AE$39=0.5,2,"")) | Z14: =IF('MAGUIKAY ES'!$AE$40=1,1,IF('MAGUIKAY ES'!$AE$40=0.5,2,"")) | AB14: =IFERROR(ROUND(AVERAGE(W14:AA14),2), "") | AC14: =IF(AB14="","",VLOOKUP(AB14,$CH$14:$CK$17,3)) | AD14: =IF('MAGUIKAY ES'!$AE$44=1,1,IF('MAGUIKAY ES'!$AE$44=0.5,2,"")) | AE14: =IF('MAGUIKAY ES'!$AE$45=1,1,IF('MAGUIKAY ES'!$AE$45=0.5,2,"")) | AF14: =IF('MAGUIKAY ES'!$AE$46=1,1,IF('MAGUIKAY ES'!$AE$46=0.5,2,"")) | AG14: =IF('MAGUIKAY ES'!$AE$47=1,1,IF('MAGUIKAY ES'!$AE$47=0.5,2,"")) | AI14: =IFERROR(ROUND(AVERAGE(AD14:AH14),2), "") | AJ14: =IF(AI14="","",VLOOKUP(AI14,$CH$14:$CK$17,3)) | AK14: =IF('MAGUIKAY ES'!$AE$51=1,1,IF('MAGUIKAY ES'!$AE$51=0.5,2,"")) | AL14: =IF('MAGUIKAY ES'!$AE$52=1,1,IF('MAGUIKAY ES'!$AE$52=0.5,2,"")) | AM14: =IF('MAGUIKAY ES'!$AE$53=1,1,IF('MAGUIKAY ES'!$AE$53=0.5,2,"")) | AN14: =IF('MAGUIKAY ES'!$AE$54=1,1,IF('MAGUIKAY ES'!$AE$54=0.5,2,"")) | AO14: =IF('MAGUIKAY ES'!$AE$55=1,1,IF('MAGUIKAY ES'!$AE$55=0.5,2,"")) | AP14: =IFERROR(ROUND(AVERAGE(AK14:AO14),2), "") | AQ14: =IF(AP14="","",VLOOKUP(AP14,$CH$14:$CK$17,3)) | AR14: =IF('MAGUIKAY ES'!$AE$58=1,1,IF('MAGUIKAY ES'!$AE$58=0.5,2,"")) | AS14: =IF('MAGUIKAY ES'!$AE$59=1,1,IF('MAGUIKAY ES'!$AE$59=0.5,2,"")) | AT14: =IF('MAGUIKAY ES'!$AE$60=1,1,IF('MAGUIKAY ES'!$AE$60=0.5,2,"")) | AU14: =IF('MAGUIKAY ES'!$AE$61=1,1,IF('MAGUIKAY ES'!$AE$61=0.5,2,"")) | AV14: =IF('MAGUIKAY ES'!$AE$62=1,1,IF('MAGUIKAY ES'!$AE$62=0.5,2,"")) | AW14: =IFERROR(ROUND(AVERAGE(AR14:AV14),2), "") | AX14: =IF(AW14="","",VLOOKUP(AW14,$CH$14:$CK$17,3)) | AY14: =IF('MAGUIKAY ES'!$AE$65=1,1,IF('MAGUIKAY ES'!$AE$65=0.5,2,"")) | AZ14: =IF('MAGUIKAY ES'!$AE$66=1,1,IF('MAGUIKAY ES'!$AE$66=0.5,2,"")) | BA14: =IF('MAGUIKAY ES'!$AE$67=1,1,IF('MAGUIKAY ES'!$AE$67=0.5,2,"")) | BB14: =IF('MAGUIKAY ES'!$AE$68=1,1,IF('MAGUIKAY ES'!$AE$68=0.5,2,"")) | BC14: =IF('MAGUIKAY ES'!$AE$69=1,1,IF('MAGUIKAY ES'!$AE$69=0.5,2,"")) | BD14: =IFERROR(ROUND(AVERAGE(AY14:BC14),2), "") | BE14: =IF(BD14="","",VLOOKUP(BD14,$CH$14:$CK$17,3)) | BF14: =IF('MAGUIKAY ES'!$AE$72=1,1,IF('MAGUIKAY ES'!$AE$72=0.5,2,"")) | BG14: =IF('MAGUIKAY ES'!$AE$73=1,1,IF('MAGUIKAY ES'!$AE$73=0.5,2,"")) | BH14: =IF('MAGUIKAY ES'!$AE$74=1,1,IF('MAGUIKAY ES'!$AE$74=0.5,2,"")) | BI14: =IF('MAGUIKAY ES'!$AE$75=1,1,IF('MAGUIKAY ES'!$AE$75=0.5,2,"")) | BJ14: =IF('MAGUIKAY ES'!$AE$76=1,1,IF('MAGUIKAY ES'!$AE$76=0.5,2,"")) | BK14: =IFERROR(ROUND(AVERAGE(BF14:BJ14),2), "") | BL14: =IF(BK14="","",VLOOKUP(BK14,$CH$14:$CK$17,3)) | CH14: 1 | CI14: 1.25 | CJ14: Fully Implemented
