Workbook

Sheet TABOK ES I
A5: Republic of the Philippines
A6: Department of Education
A8: SCHOOLS DIVISION OF MANDAUE CITY
A10: LEARNER DEVELOPMENT AND PROTECTION MONITORING CHECKLIST
A11: School: | B11: TABOK ELEMENTARY SCHOOL 1
A12: Quarter: | B12: TERM 2
A13: Monitored by: | B13: MARY JEAN B. CODIÑERA
A14: A. IDENTIFY (Early Identification of At-Risk Learners)
A15: Indicator | B15: Yes | C15: No | D15: Remarks/Evidence
A16: 1. Attendance (SF2), academic (SF5), and behavior data are regularly reviewed | AA16: TRUE | AB16: FALSE | AC16: =IF(AA16="","",IF(AA16=TRUE,1,0)) -> 1 | AD16: =IF(AB16="","",IF(AB16=TRUE,1,0)) -> 0 | AE16: =SUM(AC16:AD16) -> 1 | AF16: =IF(AE16=1,AC16,0) -> 1 | AG16: =IF(AE16=1,AD16,0) -> 0
A17: 2. Teachers maintain classroom learner tracking sheets | AA17: TRUE | AB17: FALSE | AC17: =IF(AA17="","",IF(AA17=TRUE,1,0)) -> 1 | AD17: =IF(AB17="","",IF(AB17=TRUE,1,0)) -> 0 | AE17: =SUM(AC17:AD17) -> 1 | AF17: =IF(AE17=1,AC17,0) -> 1 | AG17: =IF(AE17=1,AD17,0) -> 0
A18: 3. School has a master list of at-risk learners | AA18: TRUE | AB18: FALSE | AC18: =IF(AA18="","",IF(AA18=TRUE,1,0)) -> 1 | AD18: =IF(AB18="","",IF(AB18=TRUE,1,0)) -> 0 | AE18: =SUM(AC18:AD18) -> 1 | AF18: =IF(AE18=1,AC18,0) -> 1 | AG18: =IF(AE18=1,AD18,0) -> 0
A19: 4. At-risk learners are profiled (academic, behavioral, socio-economic factors) | AA19: TRUE | AB19: FALSE | AC19: =IF(AA19="","",IF(AA19=TRUE,1,0)) -> 1 | AD19: =IF(AB19="","",IF(AB19=TRUE,1,0)) -> 0 | AE19: =SUM(AC19:AD19) -> 1 | AF19: =IF(AE19=1,AC19,0) -> 1 | AG19: =IF(AE19=1,AD19,0) -> 0
A20: 5. Root cause analysis is conducted for identified learners | AA20: FALSE | AB20: TRUE | AC20: =IF(AA20="","",IF(AA20=TRUE,1,0)) -> 0 | AD20: =IF(AB20="","",IF(AB20=TRUE,1,0)) -> 1 | AE20: =SUM(AC20:AD20) -> 1 | AF20: =IF(AE20=1,AC20,0) -> 0 | AG20: =IF(AE20=1,AD20,0) -> 1
A21: 6. School Learner Tracking Team (SLTT) is organized and functional | AA21: FALSE | AB21: TRUE | AC21: =IF(AA21="","",IF(AA21=TRUE,1,0)) -> 0 | AD21: =IF(AB21="","",IF(AB21=TRUE,1,0)) -> 1 | AE21: =SUM(AC21:AD21) -> 1 | AF21: =IF(AE21=1,AC21,0) -> 0 | AG21: =IF(AE21=1,AD21,0) -> 1
AA22: FALSE | AB22: FALSE | AC22: =IF(AA22="","",IF(AA22=TRUE,1,0)) -> 0 | AD22: =IF(AB22="","",IF(AB22=TRUE,1,0)) -> 0 | AE22: =SUM(AC22:AD22) -> 0 | AF22: =IF(AE22=1,AC22,0) -> 0 | AG22: =IF(AE22=1,AD22,0) -> 0
AA23: FALSE | AB23: FALSE | AC23: =IF(AA23="","",IF(AA23=TRUE,1,0)) -> 0 | AD23: =IF(AB23="","",IF(AB23=TRUE,1,0)) -> 0 | AE23: =SUM(AC23:AD23) -> 0 | AF23: =IF(AE23=1,AC23,0) -> 0 | AG23: =IF(AE23=1,AD23,0) -> 0
AA24: FALSE | AB24: FALSE | AC24: =IF(AA24="","",IF(AA24=TRUE,1,0)) -> 0 | AD24: =IF(AB24="","",IF(AB24=TRUE,1,0)) -> 0 | AE24: =SUM(AC24:AD24) -> 0 | AF24: =IF(AE24=1,AC24,0) -> 0 | AG24: =IF(AE24=1,AD24,0) -> 0
AA25: FALSE | AB25: FALSE | AC25: =IF(AA25="","",IF(AA25=TRUE,1,0)) -> 0 | AD25: =IF(AB25="","",IF(AB25=TRUE,1,0)) -> 0 | AE25: =SUM(AC25:AD25) -> 0 | AF25: =IF(AE25=1,AC25,0) -> 0 | AG25: =IF(AE25=1,AD25,0) -> 0
A26: B. SUPPORT (Targeted Interventions & Differentiated Instruction) | B26: =AF26 -> 4 | C26: =AG26 -> 2 | AC26: =IF(AA26="","",IF(AA26=TRUE,1,0)) | AD26: =IF(AB26="","",IF(AB26=TRUE,1,0)) | AF26: =SUM(AF16:AF25) -> 4 | AG26: =SUM(AG16:AG25) -> 2
A27: Indicator | B27: Yes | C27: No | D27: Remarks/Evidence | AC27: =IF(AA27="","",IF(AA27=TRUE,1,0)) | AD27: =IF(AB27="","",IF(AB27=TRUE,1,0))
A28: 7. Targeted remediation programs are implemented (not general review) | AA28: TRUE | AB28: FALSE | AC28: =IF(AA28="","",IF(AA28=TRUE,1,0)) -> 1 | AD28: =IF(AB28="","",IF(AB28=TRUE,1,0)) -> 0 | AE28: =SUM(AC28:AD28) -> 1 | AF28: =IF(AE28=1,AC28,0) -> 1 | AG28: =IF(AE28=1,AD28,0) -> 0
A29: 8. Learners are grouped based on specific learning gaps | AA29: TRUE | AB29: FALSE | AC29: =IF(AA29="","",IF(AA29=TRUE,1,0)) -> 1 | AD29: =IF(AB29="","",IF(AB29=TRUE,1,0)) -> 0 | AE29: =SUM(AC29:AD29) -> 1 | AF29: =IF(AE29=1,AC29,0) -> 1 | AG29: =IF(AE29=1,AD29,0) -> 0
A30: 9. Differentiated instruction strategies are evident in teaching | AA30: TRUE | AB30: FALSE | AC30: =IF(AA30="","",IF(AA30=TRUE,1,0)) -> 1 | AD30: =IF(AB30="","",IF(AB30=TRUE,1,0)) -> 0 | AE30: =SUM(AC30:AD30) -> 1 | AF30: =IF(AE30=1,AC30,0) -> 1 | AG30: =IF(AE30=1,AD30,0) -> 0
A31: 10. Peer tutoring or learning buddy system is implemented | AA31: TRUE | AB31: FALSE | AC31: =IF(AA31="","",IF(AA31=TRUE,1,0)) -> 1 | AD31: =IF(AB31="","",IF(AB31=TRUE,1,0)) -> 0 | AE31: =SUM(AC31:AD31) -> 1 | AF31: =IF(AE31=1,AC31,0) -> 1 | AG31: =IF(AE31=1,AD31,0) -> 0
A32: 11. Counseling or psychosocial support is provided when needed | AA32: FALSE | AB32: TRUE | AC32: =IF(AA32="","",IF(AA32=TRUE,1,0)) -> 0 | AD32: =IF(AB32="","",IF(AB32=TRUE,1,0)) -> 1 | AE32: =SUM(AC32:AD32) -> 1 | AF32: =IF(AE32=1,AC32,0) -> 0 | AG32: =IF(AE32=1,AD32,0) -> 1
A33: 12. Intervention plans are documented per learner/group | AA33: FALSE | AB33: TRUE | AC33: =IF(AA33="","",IF(AA33=TRUE,1,0)) -> 0 | AD33: =IF(AB33="","",IF(AB33=TRUE,1,0)) -> 1 | AE33: =SUM(AC33:AD33) -> 1 | AF33: =IF(AE33=1,AC33,0) -> 0 | AG33: =IF(AE33=1,AD33,0) -> 1
A34: 13. Appropriate and contextualized learning materials are used | AA34: TRUE | AB34: FALSE | AC34: =IF(AA34="","",IF(AA34=TRUE,1,0)) -> 1 | AD34: =IF(AB34="","",IF(AB34=TRUE,1,0)) -> 0 | AE34: =SUM(AC34:AD34) -> 1 | AF34: =IF(AE34=1,AC34,0) -> 1 | AG34: =IF(AE34=1,AD34,0) -> 0
AA35: FALSE | AB35: FALSE | AC35: =IF(AA35="","",IF(AA35=TRUE,1,0)) -> 0 | AD35: =IF(AB35="","",IF(AB35=TRUE,1,0)) -> 0 | AE35: =SUM(AC35:AD35) -> 0 | AF35: =IF(AE35=1,AC35,0) -> 0 | AG35: =IF(AE35=1,AD35,0) -> 0
AA36: FALSE | AB36: FALSE | AC36: =IF(AA36="","",IF(AA36=TRUE,1,0)) -> 0 | AD36: =IF(AB36="","",IF(AB36=TRUE,1,0)) -> 0 | AE36: =SUM(AC36:AD36) -> 0 | AF36: =IF(AE36=1,AC36,0) -> 0 | AG36: =IF(AE36=1,AD36,0) -> 0
AA37: FALSE | AB37: FALSE | AC37: =IF(AA37="","",IF(AA37=TRUE,1,0)) -> 0 | AD37: =IF(AB37="","",IF(AB37=TRUE,1,0)) -> 0 | AE37: =SUM(AC37:AD37) -> 0 | AF37: =IF(AE37=1,AC37,0) -> 0 | AG37: =IF(AE37=1,AD37,0) -> 0
A38: C. ENGAGE (Safe, Inclusive, and Supportive Environment) | B38: =AF38 -> 5 | C38: =AG38 -> 2 | AC38: =IF(AA38="","",IF(AA38=TRUE,1,0)) | AD38: =IF(AB38="","",IF(AB38=TRUE,1,0)) | AF38: =SUM(AF28:AF37) -> 5 | AG38: =SUM(AG28:AG37) -> 2
A39: Indicator | B39: Yes | C39: No | D39: Remarks/Evidence | AC39: =IF(AA39="","",IF(AA39=TRUE,1,0)) | AD39: =IF(AB39="","",IF(AB39=TRUE,1,0))
A40: 14. SEL (Social-Emotional Learning) is integrated in daily lessons | AA40: FALSE | AB40: TRUE | AC40: =IF(AA40="","",IF(AA40=TRUE,1,0)) -> 0 | AD40: =IF(AB40="","",IF(AB40=TRUE,1,0)) -> 1 | AE40: =SUM(AC40:AD40) -> 1 | AF40: =IF(AE40=1,AC40,0) -> 0 | AG40: =IF(AE40=1,AD40,0) -> 1
A41: 15. Teachers use strategies that develop self- awareness and relationships | AA41: FALSE | AB41: TRUE | AC41: =IF(AA41="","",IF(AA41=TRUE,1,0)) -> 0 | AD41: =IF(AB41="","",IF(AB41=TRUE,1,0)) -> 1 | AE41: =SUM(AC41:AD41) -> 1 | AF41: =IF(AE41=1,AC41,0) -> 0 | AG41: =IF(AE41=1,AD41,0) -> 1
A42: 16. Classroom environment promotes respect and inclusivity | AA42: TRUE | AB42: FALSE | AC42: =IF(AA42="","",IF(AA42=TRUE,1,0)) -> 1 | AD42: =IF(AB42="","",IF(AB42=TRUE,1,0)) -> 0 | AE42: =SUM(AC42:AD42) -> 1 | AF42: =IF(AE42=1,AC42,0) -> 1 | AG42: =IF(AE42=1,AD42,0) -> 0
A43: 17. Positive discipline practices are observed (no punitive approach) | AA43: TRUE | AB43: FALSE | AC43: =IF(AA43="","",IF(AA43=TRUE,1,0)) -> 1 | AD43: =IF(AB43="","",IF(AB43=TRUE,1,0)) -> 0 | AE43: =SUM(AC43:AD43) -> 1 | AF43: =IF(AE43=1,AC43,0) -> 1 | AG43: =IF(AE43=1,AD43,0) -> 0
A44: 18. Child Protection Committee (CPC) is active and functional | D44: Need to be updated | AA44: TRUE | AB44: FALSE | AC44: =IF(AA44="","",IF(AA44=TRUE,1,0)) -> 1 | AD44: =IF(AB44="","",IF(AB44=TRUE,1,0)) -> 0 | AE44: =SUM(AC44:AD44) -> 1 | AF44: =IF(AE44=1,AC44,0) -> 1 | AG44: =IF(AE44=1,AD44,0) -> 0
A45: 19. Anti-bullying and child protection programs are implemented | AA45: TRUE | AB45: FALSE | AC45: =IF(AA45="","",IF(AA45=TRUE,1,0)) -> 1 | AD45: =IF(AB45="","",IF(AB45=TRUE,1,0)) -> 0 | AE45: =SUM(AC45:AD45) -> 1 | AF45: =IF(AE45=1,AC45,0) -> 1 | AG45: =IF(AE45=1,AD45,0) -> 0
A46: 20. Learners are given opportunities to express ideas and feelings | AA46: TRUE | AB46: FALSE | AC46: =IF(AA46="","",IF(AA46=TRUE,1,0)) -> 1 | AD46: =IF(AB46="","",IF(AB46=TRUE,1,0)) -> 0 | AE46: =SUM(AC46:AD46) -> 1 | AF46: =IF(AE46=1,AC46,0) -> 1 | AG46: =IF(AE46=1,AD46,0) -> 0
...

Sheet TABOK ES II
A5: Republic of the Philippines
A6: Department of Education
A8: SCHOOLS DIVISION OF MANDAUE CITY
A10: LEARNER DEVELOPMENT AND PROTECTION MONITORING CHECKLIST
A11: School:
A12: Quarter: | B12: TERM 2
A13: Monitored by: | B13: MARY JEAN B. CODIÑERA
A14: A. IDENTIFY (Early Identification of At-Risk Learners)
A15: Indicator | B15: Yes | C15: No | D15: Remarks/Evidence
A16: 1. Attendance (SF2), academic (SF5), and behavior data are regularly reviewed | AA16: FALSE | AB16: FALSE | AC16: =IF(AA16="","",IF(AA16=TRUE,1,0)) -> 0 | AD16: =IF(AB16="","",IF(AB16=TRUE,1,0)) -> 0 | AE16: =SUM(AC16:AD16) -> 0 | AF16: =IF(AE16=1,AC16,0) -> 0 | AG16: =IF(AE16=1,AD16,0) -> 0
A17: 2. Teachers maintain classroom learner tracking sheets | AA17: FALSE | AB17: FALSE | AC17: =IF(AA17="","",IF(AA17=TRUE,1,0)) -> 0 | AD17: =IF(AB17="","",IF(AB17=TRUE,1,0)) -> 0 | AE17: =SUM(AC17:AD17) -> 0 | AF17: =IF(AE17=1,AC17,0) -> 0 | AG17: =IF(AE17=1,AD17,0) -> 0
A18: 3. School has a master list of at-risk learners | AA18: FALSE | AB18: FALSE | AC18: =IF(AA18="","",IF(AA18=TRUE,1,0)) -> 0 | AD18: =IF(AB18="","",IF(AB18=TRUE,1,0)) -> 0 | AE18: =SUM(AC18:AD18) -> 0 | AF18: =IF(AE18=1,AC18,0) -> 0 | AG18: =IF(AE18=1,AD18,0) -> 0
A19: 4. At-risk learners are profiled (academic, behavioral, socio-economic factors) | AA19: FALSE | AB19: FALSE | AC19: =IF(AA19="","",IF(AA19=TRUE,1,0)) -> 0 | AD19: =IF(AB19="","",IF(AB19=TRUE,1,0)) -> 0 | AE19: =SUM(AC19:AD19) -> 0 | AF19: =IF(AE19=1,AC19,0) -> 0 | AG19: =IF(AE19=1,AD19,0) -> 0
A20: 5. Root cause analysis is conducted for identified learners | AA20: FALSE | AB20: FALSE | AC20: =IF(AA20="","",IF(AA20=TRUE,1,0)) -> 0 | AD20: =IF(AB20="","",IF(AB20=TRUE,1,0)) -> 0 | AE20: =SUM(AC20:AD20) -> 0 | AF20: =IF(AE20=1,AC20,0) -> 0 | AG20: =IF(AE20=1,AD20,0) -> 0
A21: 6. School Learner Tracking Team (SLTT) is organized and functional | AA21: FALSE | AB21: FALSE | AC21: =IF(AA21="","",IF(AA21=TRUE,1,0)) -> 0 | AD21: =IF(AB21="","",IF(AB21=TRUE,1,0)) -> 0 | AE21: =SUM(AC21:AD21) -> 0 | AF21: =IF(AE21=1,AC21,0) -> 0 | AG21: =IF(AE21=1,AD21,0) -> 0
AA22: FALSE | AB22: FALSE | AC22: =IF(AA22="","",IF(AA22=TRUE,1,0)) -> 0 | AD22: =IF(AB22="","",IF(AB22=TRUE,1,0)) -> 0 | AE22: =SUM(AC22:AD22) -> 0 | AF22: =IF(AE22=1,AC22,0) -> 0 | AG22: =IF(AE22=1,AD22,0) -> 0
AA23: FALSE | AB23: FALSE | AC23: =IF(AA23="","",IF(AA23=TRUE,1,0)) -> 0 | AD23: =IF(AB23="","",IF(AB23=TRUE,1,0)) -> 0 | AE23: =SUM(AC23:AD23) -> 0 | AF23: =IF(AE23=1,AC23,0) -> 0 | AG23: =IF(AE23=1,AD23,0) -> 0
AA24: FALSE | AB24: FALSE | AC24: =IF(AA24="","",IF(AA24=TRUE,1,0)) -> 0 | AD24: =IF(AB24="","",IF(AB24=TRUE,1,0)) -> 0 | AE24: =SUM(AC24:AD24) -> 0 | AF24: =IF(AE24=1,AC24,0) -> 0 | AG24: =IF(AE24=1,AD24,0) -> 0
AA25: FALSE | AB25: FALSE | AC25: =IF(AA25="","",IF(AA25=TRUE,1,0)) -> 0 | AD25: =IF(AB25="","",IF(AB25=TRUE,1,0)) -> 0 | AE25: =SUM(AC25:AD25) -> 0 | AF25: =IF(AE25=1,AC25,0) -> 0 | AG25: =IF(AE25=1,AD25,0) -> 0
A26: B. SUPPORT (Targeted Interventions & Differentiated Instruction) | B26: =AF26 -> 0 | C26: =AG26 -> 0 | AC26: =IF(AA26="","",IF(AA26=TRUE,1,0)) | AD26: =IF(AB26="","",IF(AB26=TRUE,1,0)) | AF26: =SUM(AF16:AF25) -> 0 | AG26: =SUM(AG16:AG25) -> 0
A27: Indicator | B27: Yes | C27: No | D27: Remarks/Evidence | AC27: =IF(AA27="","",IF(AA27=TRUE,1,0)) | AD27: =IF(AB27="","",IF(AB27=TRUE,1,0))
A28: 7. Targeted remediation programs are implemented (not general review) | AA28: FALSE | AB28: FALSE | AC28: =IF(AA28="","",IF(AA28=TRUE,1,0)) -> 0 | AD28: =IF(AB28="","",IF(AB28=TRUE,1,0)) -> 0 | AE28: =SUM(AC28:AD28) -> 0 | AF28: =IF(AE28=1,AC28,0) -> 0 | AG28: =IF(AE28=1,AD28,0) -> 0
A29: 8. Learners are grouped based on specific learning gaps | AA29: FALSE | AB29: FALSE | AC29: =IF(AA29="","",IF(AA29=TRUE,1,0)) -> 0 | AD29: =IF(AB29="","",IF(AB29=TRUE,1,0)) -> 0 | AE29: =SUM(AC29:AD29) -> 0 | AF29: =IF(AE29=1,AC29,0) -> 0 | AG29: =IF(AE29=1,AD29,0) -> 0
A30: 9. Differentiated instruction strategies are evident in teaching | AA30: FALSE | AB30: FALSE | AC30: =IF(AA30="","",IF(AA30=TRUE,1,0)) -> 0 | AD30: =IF(AB30="","",IF(AB30=TRUE,1,0)) -> 0 | AE30: =SUM(AC30:AD30) -> 0 | AF30: =IF(AE30=1,AC30,0) -> 0 | AG30: =IF(AE30=1,AD30,0) -> 0
A31: 10. Peer tutoring or learning buddy system is implemented | AA31: FALSE | AB31: FALSE | AC31: =IF(AA31="","",IF(AA31=TRUE,1,0)) -> 0 | AD31: =IF(AB31="","",IF(AB31=TRUE,1,0)) -> 0 | AE31: =SUM(AC31:AD31) -> 0 | AF31: =IF(AE31=1,AC31,0) -> 0 | AG31: =IF(AE31=1,AD31,0) -> 0
A32: 11. Counseling or psychosocial support is provided when needed | AA32: FALSE | AB32: FALSE | AC32: =IF(AA32="","",IF(AA32=TRUE,1,0)) -> 0 | AD32: =IF(AB32="","",IF(AB32=TRUE,1,0)) -> 0 | AE32: =SUM(AC32:AD32) -> 0 | AF32: =IF(AE32=1,AC32,0) -> 0 | AG32: =IF(AE32=1,AD32,0) -> 0
A33: 12. Intervention plans are documented per learner/group | AA33: FALSE | AB33: FALSE | AC33: =IF(AA33="","",IF(AA33=TRUE,1,0)) -> 0 | AD33: =IF(AB33="","",IF(AB33=TRUE,1,0)) -> 0 | AE33: =SUM(AC33:AD33) -> 0 | AF33: =IF(AE33=1,AC33,0) -> 0 | AG33: =IF(AE33=1,AD33,0) -> 0
A34: 13. Appropriate and contextualized learning materials are used | AA34: FALSE | AB34: FALSE | AC34: =IF(AA34="","",IF(AA34=TRUE,1,0)) -> 0 | AD34: =IF(AB34="","",IF(AB34=TRUE,1,0)) -> 0 | AE34: =SUM(AC34:AD34) -> 0 | AF34: =IF(AE34=1,AC34,0) -> 0 | AG34: =IF(AE34=1,AD34,0) -> 0
AA35: FALSE | AB35: FALSE | AC35: =IF(AA35="","",IF(AA35=TRUE,1,0)) -> 0 | AD35: =IF(AB35="","",IF(AB35=TRUE,1,0)) -> 0 | AE35: =SUM(AC35:AD35) -> 0 | AF35: =IF(AE35=1,AC35,0) -> 0 | AG35: =IF(AE35=1,AD35,0) -> 0
AA36: FALSE | AB36: FALSE | AC36: =IF(AA36="","",IF(AA36=TRUE,1,0)) -> 0 | AD36: =IF(AB36="","",IF(AB36=TRUE,1,0)) -> 0 | AE36: =SUM(AC36:AD36) -> 0 | AF36: =IF(AE36=1,AC36,0) -> 0 | AG36: =IF(AE36=1,AD36,0) -> 0
AA37: FALSE | AB37: FALSE | AC37: =IF(AA37="","",IF(AA37=TRUE,1,0)) -> 0 | AD37: =IF(AB37="","",IF(AB37=TRUE,1,0)) -> 0 | AE37: =SUM(AC37:AD37) -> 0 | AF37: =IF(AE37=1,AC37,0) -> 0 | AG37: =IF(AE37=1,AD37,0) -> 0
A38: C. ENGAGE (Safe, Inclusive, and Supportive Environment) | B38: =AF38 -> 0 | C38: =AG38 -> 0 | AC38: =IF(AA38="","",IF(AA38=TRUE,1,0)) | AD38: =IF(AB38="","",IF(AB38=TRUE,1,0)) | AF38: =SUM(AF28:AF37) -> 0 | AG38: =SUM(AG28:AG37) -> 0
A39: Indicator | B39: Yes | C39: No | D39: Remarks/Evidence | AC39: =IF(AA39="","",IF(AA39=TRUE,1,0)) | AD39: =IF(AB39="","",IF(AB39=TRUE,1,0))
A40: 14. SEL (Social-Emotional Learning) is integrated in daily lessons | AA40: FALSE | AB40: FALSE | AC40: =IF(AA40="","",IF(AA40=TRUE,1,0)) -> 0 | AD40: =IF(AB40="","",IF(AB40=TRUE,1,0)) -> 0 | AE40: =SUM(AC40:AD40) -> 0 | AF40: =IF(AE40=1,AC40,0) -> 0 | AG40: =IF(AE40=1,AD40,0) -> 0
A41: 15. Teachers use strategies that develop self- awareness and relationships | AA41: FALSE | AB41: FALSE | AC41: =IF(AA41="","",IF(AA41=TRUE,1,0)) -> 0 | AD41: =IF(AB41="","",IF(AB41=TRUE,1,0)) -> 0 | AE41: =SUM(AC41:AD41) -> 0 | AF41: =IF(AE41=1,AC41,0) -> 0 | AG41: =IF(AE41=1,AD41,0) -> 0
A42: 16. Classroom environment promotes respect and inclusivity | AA42: FALSE | AB42: FALSE | AC42: =IF(AA42="","",IF(AA42=TRUE,1,0)) -> 0 | AD42: =IF(AB42="","",IF(AB42=TRUE,1,0)) -> 0 | AE42: =SUM(AC42:AD42) -> 0 | AF42: =IF(AE42=1,AC42,0) -> 0 | AG42: =IF(AE42=1,AD42,0) -> 0
A43: 17. Positive discipline practices are observed (no punitive approach) | AA43: FALSE | AB43: FALSE | AC43: =IF(AA43="","",IF(AA43=TRUE,1,0)) -> 0 | AD43: =IF(AB43="","",IF(AB43=TRUE,1,0)) -> 0 | AE43: =SUM(AC43:AD43) -> 0 | AF43: =IF(AE43=1,AC43,0) -> 0 | AG43: =IF(AE43=1,AD43,0) -> 0
A44: 18. Child Protection Committee (CPC) is active and functional | D44: Need to be updated | AA44: FALSE | AB44: FALSE | AC44: =IF(AA44="","",IF(AA44=TRUE,1,0)) -> 0 | AD44: =IF(AB44="","",IF(AB44=TRUE,1,0)) -> 0 | AE44: =SUM(AC44:AD44) -> 0 | AF44: =IF(AE44=1,AC44,0) -> 0 | AG44: =IF(AE44=1,AD44,0) -> 0
A45: 19. Anti-bullying and child protection programs are implemented | AA45: FALSE | AB45: FALSE | AC45: =IF(AA45="","",IF(AA45=TRUE,1,0)) -> 0 | AD45: =IF(AB45="","",IF(AB45=TRUE,1,0)) -> 0 | AE45: =SUM(AC45:AD45) -> 0 | AF45: =IF(AE45=1,AC45,0) -> 0 | AG45: =IF(AE45=1,AD45,0) -> 0
A46: 20. Learners are given opportunities to express ideas and feelings | AA46: FALSE | AB46: FALSE | AC46: =IF(AA46="","",IF(AA46=TRUE,1,0)) -> 0 | AD46: =IF(AB46="","",IF(AB46=TRUE,1,0)) -> 0 | AE46: =SUM(AC46:AD46) -> 0 | AF46: =IF(AE46=1,AC46,0) -> 0 | AG46: =IF(AE46=1,AD46,0) -> 0
...

Sheet MAGUIKAY ES
A5: Republic of the Philippines
A6: Department of Education
A8: SCHOOLS DIVISION OF MANDAUE CITY
A10: LEARNER DEVELOPMENT AND PROTECTION MONITORING CHECKLIST
A11: School:
A12: Quarter: | B12: TERM 2
A13: Monitored by: | B13: MARY JEAN B. CODIÑERA
A14: A. IDENTIFY (Early Identification of At-Risk Learners)
A15: Indicator | B15: Yes | C15: No | D15: Remarks/Evidence
A16: 1. Attendance (SF2), academic (SF5), and behavior data are regularly reviewed | AA16: FALSE | AB16: FALSE | AC16: =IF(AA16="","",IF(AA16=TRUE,1,0)) -> 0 | AD16: =IF(AB16="","",IF(AB16=TRUE,1,0)) -> 0 | AE16: =SUM(AC16:AD16) -> 0 | AF16: =IF(AE16=1,AC16,0) -> 0 | AG16: =IF(AE16=1,AD16,0) -> 0
A17: 2. Teachers maintain classroom learner tracking sheets | AA17: FALSE | AB17: FALSE | AC17: =IF(AA17="","",IF(AA17=TRUE,1,0)) -> 0 | AD17: =IF(AB17="","",IF(AB17=TRUE,1,0)) -> 0 | AE17: =SUM(AC17:AD17) -> 0 | AF17: =IF(AE17=1,AC17,0) -> 0 | AG17: =IF(AE17=1,AD17,0) -> 0
A18: 3. School has a master list of at-risk learners | AA18: FALSE | AB18: FALSE | AC18: =IF(AA18="","",IF(AA18=TRUE,1,0)) -> 0 | AD18: =IF(AB18="","",IF(AB18=TRUE,1,0)) -> 0 | AE18: =SUM(AC18:AD18) -> 0 | AF18: =IF(AE18=1,AC18,0) -> 0 | AG18: =IF(AE18=1,AD18,0) -> 0
A19: 4. At-risk learners are profiled (academic, behavioral, socio-economic factors) | AA19: FALSE | AB19: FALSE | AC19: =IF(AA19="","",IF(AA19=TRUE,1,0)) -> 0 | AD19: =IF(AB19="","",IF(AB19=TRUE,1,0)) -> 0 | AE19: =SUM(AC19:AD19) -> 0 | AF19: =IF(AE19=1,AC19,0) -> 0 | AG19: =IF(AE19=1,AD19,0) -> 0
A20: 5. Root cause analysis is conducted for identified learners | AA20: FALSE | AB20: FALSE | AC20: =IF(AA20="","",IF(AA20=TRUE,1,0)) -> 0 | AD20: =IF(AB20="","",IF(AB20=TRUE,1,0)) -> 0 | AE20: =SUM(AC20:AD20) -> 0 | AF20: =IF(AE20=1,AC20,0) -> 0 | AG20: =IF(AE20=1,AD20,0) -> 0
A21: 6. School Learner Tracking Team (SLTT) is organized and functional | AA21: FALSE | AB21: FALSE | AC21: =IF(AA21="","",IF(AA21=TRUE,1,0)) -> 0 | AD21: =IF(AB21="","",IF(AB21=TRUE,1,0)) -> 0 | AE21: =SUM(AC21:AD21) -> 0 | AF21: =IF(AE21=1,AC21,0) -> 0 | AG21: =IF(AE21=1,AD21,0) -> 0
AA22: FALSE | AB22: FALSE | AC22: =IF(AA22="","",IF(AA22=TRUE,1,0)) -> 0 | AD22: =IF(AB22="","",IF(AB22=TRUE,1,0)) -> 0 | AE22: =SUM(AC22:AD22) -> 0 | AF22: =IF(AE22=1,AC22,0) -> 0 | AG22: =IF(AE22=1,AD22,0) -> 0
AA23: FALSE | AB23: FALSE | AC23: =IF(AA23="","",IF(AA23=TRUE,1,0)) -> 0 | AD23: =IF(AB23="","",IF(AB23=TRUE,1,0)) -> 0 | AE23: =SUM(AC23:AD23) -> 0 | AF23: =IF(AE23=1,AC23,0) -> 0 | AG23: =IF(AE23=1,AD23,0) -> 0
AA24: FALSE | AB24: FALSE | AC24: =IF(AA24="","",IF(AA24=TRUE,1,0)) -> 0 | AD24: =IF(AB24="","",IF(AB24=TRUE,1,0)) -> 0 | AE24: =SUM(AC24:AD24) -> 0 | AF24: =IF(AE24=1,AC24,0) -> 0 | AG24: =IF(AE24=1,AD24,0) -> 0
AA25: FALSE | AB25: FALSE | AC25: =IF(AA25="","",IF(AA25=TRUE,1,0)) -> 0 | AD25: =IF(AB25="","",IF(AB25=TRUE,1,0)) -> 0 | AE25: =SUM(AC25:AD25) -> 0 | AF25: =IF(AE25=1,AC25,0) -> 0 | AG25: =IF(AE25=1,AD25,0) -> 0
A26: B. SUPPORT (Targeted Interventions & Differentiated Instruction) | B26: =AF26 -> 0 | C26: =AG26 -> 0 | AC26: =IF(AA26="","",IF(AA26=TRUE,1,0)) | AD26: =IF(AB26="","",IF(AB26=TRUE,1,0)) | AF26: =SUM(AF16:AF25) -> 0 | AG26: =SUM(AG16:AG25) -> 0
A27: Indicator | B27: Yes | C27: No | D27: Remarks/Evidence | AC27: =IF(AA27="","",IF(AA27=TRUE,1,0)) | AD27: =IF(AB27="","",IF(AB27=TRUE,1,0))
A28: 7. Targeted remediation programs are implemented (not general review) | AA28: FALSE | AB28: FALSE | AC28: =IF(AA28="","",IF(AA28=TRUE,1,0)) -> 0 | AD28: =IF(AB28="","",IF(AB28=TRUE,1,0)) -> 0 | AE28: =SUM(AC28:AD28) -> 0 | AF28: =IF(AE28=1,AC28,0) -> 0 | AG28: =IF(AE28=1,AD28,0) -> 0
A29: 8. Learners are grouped based on specific learning gaps | AA29: FALSE | AB29: FALSE | AC29: =IF(AA29="","",IF(AA29=TRUE,1,0)) -> 0 | AD29: =IF(AB29="","",IF(AB29=TRUE,1,0)) -> 0 | AE29: =SUM(AC29:AD29) -> 0 | AF29: =IF(AE29=1,AC29,0) -> 0 | AG29: =IF(AE29=1,AD29,0) -> 0
A30: 9. Differentiated instruction strategies are evident in teaching | AA30: FALSE | AB30: FALSE | AC30: =IF(AA30="","",IF(AA30=TRUE,1,0)) -> 0 | AD30: =IF(AB30="","",IF(AB30=TRUE,1,0)) -> 0 | AE30: =SUM(AC30:AD30) -> 0 | AF30: =IF(AE30=1,AC30,0) -> 0 | AG30: =IF(AE30=1,AD30,0) -> 0
A31: 10. Peer tutoring or learning buddy system is implemented | AA31: FALSE | AB31: FALSE | AC31: =IF(AA31="","",IF(AA31=TRUE,1,0)) -> 0 | AD31: =IF(AB31="","",IF(AB31=TRUE,1,0)) -> 0 | AE31: =SUM(AC31:AD31) -> 0 | AF31: =IF(AE31=1,AC31,0) -> 0 | AG31: =IF(AE31=1,AD31,0) -> 0
A32: 11. Counseling or psychosocial support is provided when needed | AA32: FALSE | AB32: FALSE | AC32: =IF(AA32="","",IF(AA32=TRUE,1,0)) -> 0 | AD32: =IF(AB32="","",IF(AB32=TRUE,1,0)) -> 0 | AE32: =SUM(AC32:AD32) -> 0 | AF32: =IF(AE32=1,AC32,0) -> 0 | AG32: =IF(AE32=1,AD32,0) -> 0
A33: 12. Intervention plans are documented per learner/group | AA33: FALSE | AB33: FALSE | AC33: =IF(AA33="","",IF(AA33=TRUE,1,0)) -> 0 | AD33: =IF(AB33="","",IF(AB33=TRUE,1,0)) -> 0 | AE33: =SUM(AC33:AD33) -> 0 | AF33: =IF(AE33=1,AC33,0) -> 0 | AG33: =IF(AE33=1,AD33,0) -> 0
A34: 13. Appropriate and contextualized learning materials are used | AA34: FALSE | AB34: FALSE | AC34: =IF(AA34="","",IF(AA34=TRUE,1,0)) -> 0 | AD34: =IF(AB34="","",IF(AB34=TRUE,1,0)) -> 0 | AE34: =SUM(AC34:AD34) -> 0 | AF34: =IF(AE34=1,AC34,0) -> 0 | AG34: =IF(AE34=1,AD34,0) -> 0
AA35: FALSE | AB35: FALSE | AC35: =IF(AA35="","",IF(AA35=TRUE,1,0)) -> 0 | AD35: =IF(AB35="","",IF(AB35=TRUE,1,0)) -> 0 | AE35: =SUM(AC35:AD35) -> 0 | AF35: =IF(AE35=1,AC35,0) -> 0 | AG35: =IF(AE35=1,AD35,0) -> 0
AA36: FALSE | AB36: FALSE | AC36: =IF(AA36="","",IF(AA36=TRUE,1,0)) -> 0 | AD36: =IF(AB36="","",IF(AB36=TRUE,1,0)) -> 0 | AE36: =SUM(AC36:AD36) -> 0 | AF36: =IF(AE36=1,AC36,0) -> 0 | AG36: =IF(AE36=1,AD36,0) -> 0
AA37: FALSE | AB37: FALSE | AC37: =IF(AA37="","",IF(AA37=TRUE,1,0)) -> 0 | AD37: =IF(AB37="","",IF(AB37=TRUE,1,0)) -> 0 | AE37: =SUM(AC37:AD37) -> 0 | AF37: =IF(AE37=1,AC37,0) -> 0 | AG37: =IF(AE37=1,AD37,0) -> 0
A38: C. ENGAGE (Safe, Inclusive, and Supportive Environment) | B38: =AF38 -> 0 | C38: =AG38 -> 0 | AC38: =IF(AA38="","",IF(AA38=TRUE,1,0)) | AD38: =IF(AB38="","",IF(AB38=TRUE,1,0)) | AF38: =SUM(AF28:AF37) -> 0 | AG38: =SUM(AG28:AG37) -> 0
A39: Indicator | B39: Yes | C39: No | D39: Remarks/Evidence | AC39: =IF(AA39="","",IF(AA39=TRUE,1,0)) | AD39: =IF(AB39="","",IF(AB39=TRUE,1,0))
A40: 14. SEL (Social-Emotional Learning) is integrated in daily lessons | AA40: FALSE | AB40: FALSE | AC40: =IF(AA40="","",IF(AA40=TRUE,1,0)) -> 0 | AD40: =IF(AB40="","",IF(AB40=TRUE,1,0)) -> 0 | AE40: =SUM(AC40:AD40) -> 0 | AF40: =IF(AE40=1,AC40,0) -> 0 | AG40: =IF(AE40=1,AD40,0) -> 0
A41: 15. Teachers use strategies that develop self- awareness and relationships | AA41: FALSE | AB41: FALSE | AC41: =IF(AA41="","",IF(AA41=TRUE,1,0)) -> 0 | AD41: =IF(AB41="","",IF(AB41=TRUE,1,0)) -> 0 | AE41: =SUM(AC41:AD41) -> 0 | AF41: =IF(AE41=1,AC41,0) -> 0 | AG41: =IF(AE41=1,AD41,0) -> 0
A42: 16. Classroom environment promotes respect and inclusivity | AA42: FALSE | AB42: FALSE | AC42: =IF(AA42="","",IF(AA42=TRUE,1,0)) -> 0 | AD42: =IF(AB42="","",IF(AB42=TRUE,1,0)) -> 0 | AE42: =SUM(AC42:AD42) -> 0 | AF42: =IF(AE42=1,AC42,0) -> 0 | AG42: =IF(AE42=1,AD42,0) -> 0
A43: 17. Positive discipline practices are observed (no punitive approach) | AA43: FALSE | AB43: FALSE | AC43: =IF(AA43="","",IF(AA43=TRUE,1,0)) -> 0 | AD43: =IF(AB43="","",IF(AB43=TRUE,1,0)) -> 0 | AE43: =SUM(AC43:AD43) -> 0 | AF43: =IF(AE43=1,AC43,0) -> 0 | AG43: =IF(AE43=1,AD43,0) -> 0
A44: 18. Child Protection Committee (CPC) is active and functional | D44: Need to be updated | AA44: FALSE | AB44: FALSE | AC44: =IF(AA44="","",IF(AA44=TRUE,1,0)) -> 0 | AD44: =IF(AB44="","",IF(AB44=TRUE,1,0)) -> 0 | AE44: =SUM(AC44:AD44) -> 0 | AF44: =IF(AE44=1,AC44,0) -> 0 | AG44: =IF(AE44=1,AD44,0) -> 0
A45: 19. Anti-bullying and child protection programs are implemented | AA45: FALSE | AB45: FALSE | AC45: =IF(AA45="","",IF(AA45=TRUE,1,0)) -> 0 | AD45: =IF(AB45="","",IF(AB45=TRUE,1,0)) -> 0 | AE45: =SUM(AC45:AD45) -> 0 | AF45: =IF(AE45=1,AC45,0) -> 0 | AG45: =IF(AE45=1,AD45,0) -> 0
A46: 20. Learners are given opportunities to express ideas and feelings | AA46: FALSE | AB46: FALSE | AC46: =IF(AA46="","",IF(AA46=TRUE,1,0)) -> 0 | AD46: =IF(AB46="","",IF(AB46=TRUE,1,0)) -> 0 | AE46: =SUM(AC46:AD46) -> 0 | AF46: =IF(AE46=1,AC46,0) -> 0 | AG46: =IF(AE46=1,AD46,0) -> 0
...

Sheet CABANCALAN I ES
A5: Republic of the Philippines
A6: Department of Education
A8: SCHOOLS DIVISION OF MANDAUE CITY
A10: LEARNER DEVELOPMENT AND PROTECTION MONITORING CHECKLIST
A11: School:
A12: Quarter: | B12: TERM 2
A13: Monitored by: | B13: MARY JEAN B. CODIÑERA
A14: A. IDENTIFY (Early Identification of At-Risk Learners)
A15: Indicator | B15: Yes | C15: No | D15: Remarks/Evidence
A16: 1. Attendance (SF2), academic (SF5), and behavior data are regularly reviewed | AA16: FALSE | AB16: FALSE | AC16: =IF(AA16="","",IF(AA16=TRUE,1,0)) -> 0 | AD16: =IF(AB16="","",IF(AB16=TRUE,1,0)) -> 0 | AE16: =SUM(AC16:AD16) -> 0 | AF16: =IF(AE16=1,AC16,0) -> 0 | AG16: =IF(AE16=1,AD16,0) -> 0
A17: 2. Teachers maintain classroom learner tracking sheets | AA17: FALSE | AB17: FALSE | AC17: =IF(AA17="","",IF(AA17=TRUE,1,0)) -> 0 | AD17: =IF(AB17="","",IF(AB17=TRUE,1,0)) -> 0 | AE17: =SUM(AC17:AD17) -> 0 | AF17: =IF(AE17=1,AC17,0) -> 0 | AG17: =IF(AE17=1,AD17,0) -> 0
A18: 3. School has a master list of at-risk learners | AA18: FALSE | AB18: FALSE | AC18: =IF(AA18="","",IF(AA18=TRUE,1,0)) -> 0 | AD18: =IF(AB18="","",IF(AB18=TRUE,1,0)) -> 0 | AE18: =SUM(AC18:AD18) -> 0 | AF18: =IF(AE18=1,AC18,0) -> 0 | AG18: =IF(AE18=1,AD18,0) -> 0
A19: 4. At-risk learners are profiled (academic, behavioral, socio-economic factors) | AA19: FALSE | AB19: FALSE | AC19: =IF(AA19="","",IF(AA19=TRUE,1,0)) -> 0 | AD19: =IF(AB19="","",IF(AB19=TRUE,1,0)) -> 0 | AE19: =SUM(AC19:AD19) -> 0 | AF19: =IF(AE19=1,AC19,0) -> 0 | AG19: =IF(AE19=1,AD19,0) -> 0
A20: 5. Root cause analysis is conducted for identified learners | AA20: FALSE | AB20: FALSE | AC20: =IF(AA20="","",IF(AA20=TRUE,1,0)) -> 0 | AD20: =IF(AB20="","",IF(AB20=TRUE,1,0)) -> 0 | AE20: =SUM(AC20:AD20) -> 0 | AF20: =IF(AE20=1,AC20,0) -> 0 | AG20: =IF(AE20=1,AD20,0) -> 0
A21: 6. School Learner Tracking Team (SLTT) is organized and functional | AA21: FALSE | AB21: FALSE | AC21: =IF(AA21="","",IF(AA21=TRUE,1,0)) -> 0 | AD21: =IF(AB21="","",IF(AB21=TRUE,1,0)) -> 0 | AE21: =SUM(AC21:AD21) -> 0 | AF21: =IF(AE21=1,AC21,0) -> 0 | AG21: =IF(AE21=1,AD21,0) -> 0
AA22: FALSE | AB22: FALSE | AC22: =IF(AA22="","",IF(AA22=TRUE,1,0)) -> 0 | AD22: =IF(AB22="","",IF(AB22=TRUE,1,0)) -> 0 | AE22: =SUM(AC22:AD22) -> 0 | AF22: =IF(AE22=1,AC22,0) -> 0 | AG22: =IF(AE22=1,AD22,0) -> 0
AA23: FALSE | AB23: FALSE | AC23: =IF(AA23="","",IF(AA23=TRUE,1,0)) -> 0 | AD23: =IF(AB23="","",IF(AB23=TRUE,1,0)) -> 0 | AE23: =SUM(AC23:AD23) -> 0 | AF23: =IF(AE23=1,AC23,0) -> 0 | AG23: =IF(AE23=1,AD23,0) -> 0
AA24: FALSE | AB24: FALSE | AC24: =IF(AA24="","",IF(AA24=TRUE,1,0)) -> 0 | AD24: =IF(AB24="","",IF(AB24=TRUE,1,0)) -> 0 | AE24: =SUM(AC24:AD24) -> 0 | AF24: =IF(AE24=1,AC24,0) -> 0 | AG24: =IF(AE24=1,AD24,0) -> 0
AA25: FALSE | AB25: FALSE | AC25: =IF(AA25="","",IF(AA25=TRUE,1,0)) -> 0 | AD25: =IF(AB25="","",IF(AB25=TRUE,1,0)) -> 0 | AE25: =SUM(AC25:AD25) -> 0 | AF25: =IF(AE25=1,AC25,0) -> 0 | AG25: =IF(AE25=1,AD25,0) -> 0
A26: B. SUPPORT (Targeted Interventions & Differentiated Instruction) | B26: =AF26 -> 0 | C26: =AG26 -> 0 | AC26: =IF(AA26="","",IF(AA26=TRUE,1,0)) | AD26: =IF(AB26="","",IF(AB26=TRUE,1,0)) | AF26: =SUM(AF16:AF25) -> 0 | AG26: =SUM(AG16:AG25) -> 0
A27: Indicator | B27: Yes | C27: No | D27: Remarks/Evidence | AC27: =IF(AA27="","",IF(AA27=TRUE,1,0)) | AD27: =IF(AB27="","",IF(AB27=TRUE,1,0))
A28: 7. Targeted remediation programs are implemented (not general review) | AA28: FALSE | AB28: FALSE | AC28: =IF(AA28="","",IF(AA28=TRUE,1,0)) -> 0 | AD28: =IF(AB28="","",IF(AB28=TRUE,1,0)) -> 0 | AE28: =SUM(AC28:AD28) -> 0 | AF28: =IF(AE28=1,AC28,0) -> 0 | AG28: =IF(AE28=1,AD28,0) -> 0
A29: 8. Learners are grouped based on specific learning gaps | AA29: FALSE | AB29: FALSE | AC29: =IF(AA29="","",IF(AA29=TRUE,1,0)) -> 0 | AD29: =IF(AB29="","",IF(AB29=TRUE,1,0)) -> 0 | AE29: =SUM(AC29:AD29) -> 0 | AF29: =IF(AE29=1,AC29,0) -> 0 | AG29: =IF(AE29=1,AD29,0) -> 0
A30: 9. Differentiated instruction strategies are evident in teaching | AA30: FALSE | AB30: FALSE | AC30: =IF(AA30="","",IF(AA30=TRUE,1,0)) -> 0 | AD30: =IF(AB30="","",IF(AB30=TRUE,1,0)) -> 0 | AE30: =SUM(AC30:AD30) -> 0 | AF30: =IF(AE30=1,AC30,0) -> 0 | AG30: =IF(AE30=1,AD30,0) -> 0
A31: 10. Peer tutoring or learning buddy system is implemented | AA31: FALSE | AB31: FALSE | AC31: =IF(AA31="","",IF(AA31=TRUE,1,0)) -> 0 | AD31: =IF(AB31="","",IF(AB31=TRUE,1,0)) -> 0 | AE31: =SUM(AC31:AD31) -> 0 | AF31: =IF(AE31=1,AC31,0) -> 0 | AG31: =IF(AE31=1,AD31,0) -> 0
A32: 11. Counseling or psychosocial support is provided when needed | AA32: FALSE | AB32: FALSE | AC32: =IF(AA32="","",IF(AA32=TRUE,1,0)) -> 0 | AD32: =IF(AB32="","",IF(AB32=TRUE,1,0)) -> 0 | AE32: =SUM(AC32:AD32) -> 0 | AF32: =IF(AE32=1,AC32,0) -> 0 | AG32: =IF(AE32=1,AD32,0) -> 0
A33: 12. Intervention plans are documented per learner/group | AA33: FALSE | AB33: FALSE | AC33: =IF(AA33="","",IF(AA33=TRUE,1,0)) -> 0 | AD33: =IF(AB33="","",IF(AB33=TRUE,1,0)) -> 0 | AE33: =SUM(AC33:AD33) -> 0 | AF33: =IF(AE33=1,AC33,0) -> 0 | AG33: =IF(AE33=1,AD33,0) -> 0
A34: 13. Appropriate and contextualized learning materials are used | AA34: FALSE | AB34: FALSE | AC34: =IF(AA34="","",IF(AA34=TRUE,1,0)) -> 0 | AD34: =IF(AB34="","",IF(AB34=TRUE,1,0)) -> 0 | AE34: =SUM(AC34:AD34) -> 0 | AF34: =IF(AE34=1,AC34,0) -> 0 | AG34: =IF(AE34=1,AD34,0) -> 0
AA35: FALSE | AB35: FALSE | AC35: =IF(AA35="","",IF(AA35=TRUE,1,0)) -> 0 | AD35: =IF(AB35="","",IF(AB35=TRUE,1,0)) -> 0 | AE35: =SUM(AC35:AD35) -> 0 | AF35: =IF(AE35=1,AC35,0) -> 0 | AG35: =IF(AE35=1,AD35,0) -> 0
AA36: FALSE | AB36: FALSE | AC36: =IF(AA36="","",IF(AA36=TRUE,1,0)) -> 0 | AD36: =IF(AB36="","",IF(AB36=TRUE,1,0)) -> 0 | AE36: =SUM(AC36:AD36) -> 0 | AF36: =IF(AE36=1,AC36,0) -> 0 | AG36: =IF(AE36=1,AD36,0) -> 0
AA37: FALSE | AB37: FALSE | AC37: =IF(AA37="","",IF(AA37=TRUE,1,0)) -> 0 | AD37: =IF(AB37="","",IF(AB37=TRUE,1,0)) -> 0 | AE37: =SUM(AC37:AD37) -> 0 | AF37: =IF(AE37=1,AC37,0) -> 0 | AG37: =IF(AE37=1,AD37,0) -> 0
A38: C. ENGAGE (Safe, Inclusive, and Supportive Environment) | B38: =AF38 -> 0 | C38: =AG38 -> 0 | AC38: =IF(AA38="","",IF(AA38=TRUE,1,0)) | AD38: =IF(AB38="","",IF(AB38=TRUE,1,0)) | AF38: =SUM(AF28:AF37) -> 0 | AG38: =SUM(AG28:AG37) -> 0
A39: Indicator | B39: Yes | C39: No | D39: Remarks/Evidence | AC39: =IF(AA39="","",IF(AA39=TRUE,1,0)) | AD39: =IF(AB39="","",IF(AB39=TRUE,1,0))
A40: 14. SEL (Social-Emotional Learning) is integrated in daily lessons | AA40: FALSE | AB40: FALSE | AC40: =IF(AA40="","",IF(AA40=TRUE,1,0)) -> 0 | AD40: =IF(AB40="","",IF(AB40=TRUE,1,0)) -> 0 | AE40: =SUM(AC40:AD40) -> 0 | AF40: =IF(AE40=1,AC40,0) -> 0 | AG40: =IF(AE40=1,AD40,0) -> 0
A41: 15. Teachers use strategies that develop self- awareness and relationships | AA41: FALSE | AB41: FALSE | AC41: =IF(AA41="","",IF(AA41=TRUE,1,0)) -> 0 | AD41: =IF(AB41="","",IF(AB41=TRUE,1,0)) -> 0 | AE41: =SUM(AC41:AD41) -> 0 | AF41: =IF(AE41=1,AC41,0) -> 0 | AG41: =IF(AE41=1,AD41,0) -> 0
A42: 16. Classroom environment promotes respect and inclusivity | AA42: FALSE | AB42: FALSE | AC42: =IF(AA42="","",IF(AA42=TRUE,1,0)) -> 0 | AD42: =IF(AB42="","",IF(AB42=TRUE,1,0)) -> 0 | AE42: =SUM(AC42:AD42) -> 0 | AF42: =IF(AE42=1,AC42,0) -> 0 | AG42: =IF(AE42=1,AD42,0) -> 0
A43: 17. Positive discipline practices are observed (no punitive approach) | AA43: FALSE | AB43: FALSE | AC43: =IF(AA43="","",IF(AA43=TRUE,1,0)) -> 0 | AD43: =IF(AB43="","",IF(AB43=TRUE,1,0)) -> 0 | AE43: =SUM(AC43:AD43) -> 0 | AF43: =IF(AE43=1,AC43,0) -> 0 | AG43: =IF(AE43=1,AD43,0) -> 0
A44: 18. Child Protection Committee (CPC) is active and functional | D44: Need to be updated | AA44: FALSE | AB44: FALSE | AC44: =IF(AA44="","",IF(AA44=TRUE,1,0)) -> 0 | AD44: =IF(AB44="","",IF(AB44=TRUE,1,0)) -> 0 | AE44: =SUM(AC44:AD44) -> 0 | AF44: =IF(AE44=1,AC44,0) -> 0 | AG44: =IF(AE44=1,AD44,0) -> 0
A45: 19. Anti-bullying and child protection programs are implemented | AA45: FALSE | AB45: FALSE | AC45: =IF(AA45="","",IF(AA45=TRUE,1,0)) -> 0 | AD45: =IF(AB45="","",IF(AB45=TRUE,1,0)) -> 0 | AE45: =SUM(AC45:AD45) -> 0 | AF45: =IF(AE45=1,AC45,0) -> 0 | AG45: =IF(AE45=1,AD45,0) -> 0
A46: 20. Learners are given opportunities to express ideas and feelings | AA46: FALSE | AB46: FALSE | AC46: =IF(AA46="","",IF(AA46=TRUE,1,0)) -> 0 | AD46: =IF(AB46="","",IF(AB46=TRUE,1,0)) -> 0 | AE46: =SUM(AC46:AD46) -> 0 | AF46: =IF(AE46=1,AC46,0) -> 0 | AG46: =IF(AE46=1,AD46,0) -> 0
...

Sheet BAKILID ES
A5: Republic of the Philippines
A6: Department of Education
A8: SCHOOLS DIVISION OF MANDAUE CITY
A10: LEARNER DEVELOPMENT AND PROTECTION MONITORING CHECKLIST
A11: School:
A12: Quarter: | B12: TERM 2
A13: Monitored by: | B13: MARY JEAN B. CODIÑERA
A14: A. IDENTIFY (Early Identification of At-Risk Learners)
A15: Indicator | B15: Yes | C15: No | D15: Remarks/Evidence
A16: 1. Attendance (SF2), academic (SF5), and behavior data are regularly reviewed | AA16: FALSE | AB16: FALSE | AC16: =IF(AA16="","",IF(AA16=TRUE,1,0)) -> 0 | AD16: =IF(AB16="","",IF(AB16=TRUE,1,0)) -> 0 | AE16: =SUM(AC16:AD16) -> 0 | AF16: =IF(AE16=1,AC16,0) -> 0 | AG16: =IF(AE16=1,AD16,0) -> 0
A17: 2. Teachers maintain classroom learner tracking sheets | AA17: FALSE | AB17: FALSE | AC17: =IF(AA17="","",IF(AA17=TRUE,1,0)) -> 0 | AD17: =IF(AB17="","",IF(AB17=TRUE,1,0)) -> 0 | AE17: =SUM(AC17:AD17) -> 0 | AF17: =IF(AE17=1,AC17,0) -> 0 | AG17: =IF(AE17=1,AD17,0) -> 0
A18: 3. School has a master list of at-risk learners | AA18: FALSE | AB18: FALSE | AC18: =IF(AA18="","",IF(AA18=TRUE,1,0)) -> 0 | AD18: =IF(AB18="","",IF(AB18=TRUE,1,0)) -> 0 | AE18: =SUM(AC18:AD18) -> 0 | AF18: =IF(AE18=1,AC18,0) -> 0 | AG18: =IF(AE18=1,AD18,0) -> 0
A19: 4. At-risk learners are profiled (academic, behavioral, socio-economic factors) | AA19: FALSE | AB19: FALSE | AC19: =IF(AA19="","",IF(AA19=TRUE,1,0)) -> 0 | AD19: =IF(AB19="","",IF(AB19=TRUE,1,0)) -> 0 | AE19: =SUM(AC19:AD19) -> 0 | AF19: =IF(AE19=1,AC19,0) -> 0 | AG19: =IF(AE19=1,AD19,0) -> 0
A20: 5. Root cause analysis is conducted for identified learners | AA20: FALSE | AB20: FALSE | AC20: =IF(AA20="","",IF(AA20=TRUE,1,0)) -> 0 | AD20: =IF(AB20="","",IF(AB20=TRUE,1,0)) -> 0 | AE20: =SUM(AC20:AD20) -> 0 | AF20: =IF(AE20=1,AC20,0) -> 0 | AG20: =IF(AE20=1,AD20,0) -> 0
A21: 6. School Learner Tracking Team (SLTT) is organized and functional | AA21: FALSE | AB21: FALSE | AC21: =IF(AA21="","",IF(AA21=TRUE,1,0)) -> 0 | AD21: =IF(AB21="","",IF(AB21=TRUE,1,0)) -> 0 | AE21: =SUM(AC21:AD21) -> 0 | AF21: =IF(AE21=1,AC21,0) -> 0 | AG21: =IF(AE21=1,AD21,0) -> 0
AA22: FALSE | AB22: FALSE | AC22: =IF(AA22="","",IF(AA22=TRUE,1,0)) -> 0 | AD22: =IF(AB22="","",IF(AB22=TRUE,1,0)) -> 0 | AE22: =SUM(AC22:AD22) -> 0 | AF22: =IF(AE22=1,AC22,0) -> 0 | AG22: =IF(AE22=1,AD22,0) -> 0
AA23: FALSE | AB23: FALSE | AC23: =IF(AA23="","",IF(AA23=TRUE,1,0)) -> 0 | AD23: =IF(AB23="","",IF(AB23=TRUE,1,0)) -> 0 | AE23: =SUM(AC23:AD23) -> 0 | AF23: =IF(AE23=1,AC23,0) -> 0 | AG23: =IF(AE23=1,AD23,0) -> 0
AA24: FALSE | AB24: FALSE | AC24: =IF(AA24="","",IF(AA24=TRUE,1,0)) -> 0 | AD24: =IF(AB24="","",IF(AB24=TRUE,1,0)) -> 0 | AE24: =SUM(AC24:AD24) -> 0 | AF24: =IF(AE24=1,AC24,0) -> 0 | AG24: =IF(AE24=1,AD24,0) -> 0
AA25: FALSE | AB25: FALSE | AC25: =IF(AA25="","",IF(AA25=TRUE,1,0)) -> 0 | AD25: =IF(AB25="","",IF(AB25=TRUE,1,0)) -> 0 | AE25: =SUM(AC25:AD25) -> 0 | AF25: =IF(AE25=1,AC25,0) -> 0 | AG25: =IF(AE25=1,AD25,0) -> 0
A26: B. SUPPORT (Targeted Interventions & Differentiated Instruction) | B26: =AF26 -> 0 | C26: =AG26 -> 0 | AC26: =IF(AA26="","",IF(AA26=TRUE,1,0)) | AD26: =IF(AB26="","",IF(AB26=TRUE,1,0)) | AF26: =SUM(AF16:AF25) -> 0 | AG26: =SUM(AG16:AG25) -> 0
A27: Indicator | B27: Yes | C27: No | D27: Remarks/Evidence | AC27: =IF(AA27="","",IF(AA27=TRUE,1,0)) | AD27: =IF(AB27="","",IF(AB27=TRUE,1,0))
A28: 7. Targeted remediation programs are implemented (not general review) | AA28: FALSE | AB28: FALSE | AC28: =IF(AA28="","",IF(AA28=TRUE,1,0)) -> 0 | AD28: =IF(AB28="","",IF(AB28=TRUE,1,0)) -> 0 | AE28: =SUM(AC28:AD28) -> 0 | AF28: =IF(AE28=1,AC28,0) -> 0 | AG28: =IF(AE28=1,AD28,0) -> 0
A29: 8. Learners are grouped based on specific learning gaps | AA29: FALSE | AB29: FALSE | AC29: =IF(AA29="","",IF(AA29=TRUE,1,0)) -> 0 | AD29: =IF(AB29="","",IF(AB29=TRUE,1,0)) -> 0 | AE29: =SUM(AC29:AD29) -> 0 | AF29: =IF(AE29=1,AC29,0) -> 0 | AG29: =IF(AE29=1,AD29,0) -> 0
A30: 9. Differentiated instruction strategies are evident in teaching | AA30: FALSE | AB30: FALSE | AC30: =IF(AA30="","",IF(AA30=TRUE,1,0)) -> 0 | AD30: =IF(AB30="","",IF(AB30=TRUE,1,0)) -> 0 | AE30: =SUM(AC30:AD30) -> 0 | AF30: =IF(AE30=1,AC30,0) -> 0 | AG30: =IF(AE30=1,AD30,0) -> 0
A31: 10. Peer tutoring or learning buddy system is implemented | AA31: FALSE | AB31: FALSE | AC31: =IF(AA31="","",IF(AA31=TRUE,1,0)) -> 0 | AD31: =IF(AB31="","",IF(AB31=TRUE,1,0)) -> 0 | AE31: =SUM(AC31:AD31) -> 0 | AF31: =IF(AE31=1,AC31,0) -> 0 | AG31: =IF(AE31=1,AD31,0) -> 0
A32: 11. Counseling or psychosocial support is provided when needed | AA32: FALSE | AB32: FALSE | AC32: =IF(AA32="","",IF(AA32=TRUE,1,0)) -> 0 | AD32: =IF(AB32="","",IF(AB32=TRUE,1,0)) -> 0 | AE32: =SUM(AC32:AD32) -> 0 | AF32: =IF(AE32=1,AC32,0) -> 0 | AG32: =IF(AE32=1,AD32,0) -> 0
A33: 12. Intervention plans are documented per learner/group | AA33: FALSE | AB33: FALSE | AC33: =IF(AA33="","",IF(AA33=TRUE,1,0)) -> 0 | AD33: =IF(AB33="","",IF(AB33=TRUE,1,0)) -> 0 | AE33: =SUM(AC33:AD33) -> 0 | AF33: =IF(AE33=1,AC33,0) -> 0 | AG33: =IF(AE33=1,AD33,0) -> 0
A34: 13. Appropriate and contextualized learning materials are used | AA34: FALSE | AB34: FALSE | AC34: =IF(AA34="","",IF(AA34=TRUE,1,0)) -> 0 | AD34: =IF(AB34="","",IF(AB34=TRUE,1,0)) -> 0 | AE34: =SUM(AC34:AD34) -> 0 | AF34: =IF(AE34=1,AC34,0) -> 0 | AG34: =IF(AE34=1,AD34,0) -> 0
AA35: FALSE | AB35: FALSE | AC35: =IF(AA35="","",IF(AA35=TRUE,1,0)) -> 0 | AD35: =IF(AB35="","",IF(AB35=TRUE,1,0)) -> 0 | AE35: =SUM(AC35:AD35) -> 0 | AF35: =IF(AE35=1,AC35,0) -> 0 | AG35: =IF(AE35=1,AD35,0) -> 0
AA36: FALSE | AB36: FALSE | AC36: =IF(AA36="","",IF(AA36=TRUE,1,0)) -> 0 | AD36: =IF(AB36="","",IF(AB36=TRUE,1,0)) -> 0 | AE36: =SUM(AC36:AD36) -> 0 | AF36: =IF(AE36=1,AC36,0) -> 0 | AG36: =IF(AE36=1,AD36,0) -> 0
AA37: FALSE | AB37: FALSE | AC37: =IF(AA37="","",IF(AA37=TRUE,1,0)) -> 0 | AD37: =IF(AB37="","",IF(AB37=TRUE,1,0)) -> 0 | AE37: =SUM(AC37:AD37) -> 0 | AF37: =IF(AE37=1,AC37,0) -> 0 | AG37: =IF(AE37=1,AD37,0) -> 0
A38: C. ENGAGE (Safe, Inclusive, and Supportive Environment) | B38: =AF38 -> 0 | C38: =AG38 -> 0 | AC38: =IF(AA38="","",IF(AA38=TRUE,1,0)) | AD38: =IF(AB38="","",IF(AB38=TRUE,1,0)) | AF38: =SUM(AF28:AF37) -> 0 | AG38: =SUM(AG28:AG37) -> 0
A39: Indicator | B39: Yes | C39: No | D39: Remarks/Evidence | AC39: =IF(AA39="","",IF(AA39=TRUE,1,0)) | AD39: =IF(AB39="","",IF(AB39=TRUE,1,0))
A40: 14. SEL (Social-Emotional Learning) is integrated in daily lessons | AA40: FALSE | AB40: FALSE | AC40: =IF(AA40="","",IF(AA40=TRUE,1,0)) -> 0 | AD40: =IF(AB40="","",IF(AB40=TRUE,1,0)) -> 0 | AE40: =SUM(AC40:AD40) -> 0 | AF40: =IF(AE40=1,AC40,0) -> 0 | AG40: =IF(AE40=1,AD40,0) -> 0
A41: 15. Teachers use strategies that develop self- awareness and relationships | AA41: FALSE | AB41: FALSE | AC41: =IF(AA41="","",IF(AA41=TRUE,1,0)) -> 0 | AD41: =IF(AB41="","",IF(AB41=TRUE,1,0)) -> 0 | AE41: =SUM(AC41:AD41) -> 0 | AF41: =IF(AE41=1,AC41,0) -> 0 | AG41: =IF(AE41=1,AD41,0) -> 0
A42: 16. Classroom environment promotes respect and inclusivity | AA42: FALSE | AB42: FALSE | AC42: =IF(AA42="","",IF(AA42=TRUE,1,0)) -> 0 | AD42: =IF(AB42="","",IF(AB42=TRUE,1,0)) -> 0 | AE42: =SUM(AC42:AD42) -> 0 | AF42: =IF(AE42=1,AC42,0) -> 0 | AG42: =IF(AE42=1,AD42,0) -> 0
A43: 17. Positive discipline practices are observed (no punitive approach) | AA43: FALSE | AB43: FALSE | AC43: =IF(AA43="","",IF(AA43=TRUE,1,0)) -> 0 | AD43: =IF(AB43="","",IF(AB43=TRUE,1,0)) -> 0 | AE43: =SUM(AC43:AD43) -> 0 | AF43: =IF(AE43=1,AC43,0) -> 0 | AG43: =IF(AE43=1,AD43,0) -> 0
A44: 18. Child Protection Committee (CPC) is active and functional | D44: Need to be updated | AA44: FALSE | AB44: FALSE | AC44: =IF(AA44="","",IF(AA44=TRUE,1,0)) -> 0 | AD44: =IF(AB44="","",IF(AB44=TRUE,1,0)) -> 0 | AE44: =SUM(AC44:AD44) -> 0 | AF44: =IF(AE44=1,AC44,0) -> 0 | AG44: =IF(AE44=1,AD44,0) -> 0
A45: 19. Anti-bullying and child protection programs are implemented | AA45: FALSE | AB45: FALSE | AC45: =IF(AA45="","",IF(AA45=TRUE,1,0)) -> 0 | AD45: =IF(AB45="","",IF(AB45=TRUE,1,0)) -> 0 | AE45: =SUM(AC45:AD45) -> 0 | AF45: =IF(AE45=1,AC45,0) -> 0 | AG45: =IF(AE45=1,AD45,0) -> 0
A46: 20. Learners are given opportunities to express ideas and feelings | AA46: FALSE | AB46: FALSE | AC46: =IF(AA46="","",IF(AA46=TRUE,1,0)) -> 0 | AD46: =IF(AB46="","",IF(AB46=TRUE,1,0)) -> 0 | AE46: =SUM(AC46:AD46) -> 0 | AF46: =IF(AE46=1,AC46,0) -> 0 | AG46: =IF(AE46=1,AD46,0) -> 0
...

Sheet TINGUB ES
A5: Republic of the Philippines
A6: Department of Education
A8: SCHOOLS DIVISION OF MANDAUE CITY
A10: LEARNER DEVELOPMENT AND PROTECTION MONITORING CHECKLIST
A11: School:
A12: Quarter: | B12: TERM 2
A13: Monitored by: | B13: MARY JEAN B. CODIÑERA
A14: A. IDENTIFY (Early Identification of At-Risk Learners)
A15: Indicator | B15: Yes | C15: No | D15: Remarks/Evidence
A16: 1. Attendance (SF2), academic (SF5), and behavior data are regularly reviewed | AA16: FALSE | AB16: FALSE | AC16: =IF(AA16="","",IF(AA16=TRUE,1,0)) -> 0 | AD16: =IF(AB16="","",IF(AB16=TRUE,1,0)) -> 0 | AE16: =SUM(AC16:AD16) -> 0 | AF16: =IF(AE16=1,AC16,0) -> 0 | AG16: =IF(AE16=1,AD16,0) -> 0
A17: 2. Teachers maintain classroom learner tracking sheets | AA17: FALSE | AB17: FALSE | AC17: =IF(AA17="","",IF(AA17=TRUE,1,0)) -> 0 | AD17: =IF(AB17="","",IF(AB17=TRUE,1,0)) -> 0 | AE17: =SUM(AC17:AD17) -> 0 | AF17: =IF(AE17=1,AC17,0) -> 0 | AG17: =IF(AE17=1,AD17,0) -> 0
A18: 3. School has a master list of at-risk learners | AA18: FALSE | AB18: FALSE | AC18: =IF(AA18="","",IF(AA18=TRUE,1,0)) -> 0 | AD18: =IF(AB18="","",IF(AB18=TRUE,1,0)) -> 0 | AE18: =SUM(AC18:AD18) -> 0 | AF18: =IF(AE18=1,AC18,0) -> 0 | AG18: =IF(AE18=1,AD18,0) -> 0
A19: 4. At-risk learners are profiled (academic, behavioral, socio-economic factors) | AA19: FALSE | AB19: FALSE | AC19: =IF(AA19="","",IF(AA19=TRUE,1,0)) -> 0 | AD19: =IF(AB19="","",IF(AB19=TRUE,1,0)) -> 0 | AE19: =SUM(AC19:AD19) -> 0 | AF19: =IF(AE19=1,AC19,0) -> 0 | AG19: =IF(AE19=1,AD19,0) -> 0
A20: 5. Root cause analysis is conducted for identified learners | AA20: FALSE | AB20: FALSE | AC20: =IF(AA20="","",IF(AA20=TRUE,1,0)) -> 0 | AD20: =IF(AB20="","",IF(AB20=TRUE,1,0)) -> 0 | AE20: =SUM(AC20:AD20) -> 0 | AF20: =IF(AE20=1,AC20,0) -> 0 | AG20: =IF(AE20=1,AD20,0) -> 0
A21: 6. School Learner Tracking Team (SLTT) is organized and functional | AA21: FALSE | AB21: FALSE | AC21: =IF(AA21="","",IF(AA21=TRUE,1,0)) -> 0 | AD21: =IF(AB21="","",IF(AB21=TRUE,1,0)) -> 0 | AE21: =SUM(AC21:AD21) -> 0 | AF21: =IF(AE21=1,AC21,0) -> 0 | AG21: =IF(AE21=1,AD21,0) -> 0
AA22: FALSE | AB22: FALSE | AC22: =IF(AA22="","",IF(AA22=TRUE,1,0)) -> 0 | AD22: =IF(AB22="","",IF(AB22=TRUE,1,0)) -> 0 | AE22: =SUM(AC22:AD22) -> 0 | AF22: =IF(AE22=1,AC22,0) -> 0 | AG22: =IF(AE22=1,AD22,0) -> 0
AA23: FALSE | AB23: FALSE | AC23: =IF(AA23="","",IF(AA23=TRUE,1,0)) -> 0 | AD23: =IF(AB23="","",IF(AB23=TRUE,1,0)) -> 0 | AE23: =SUM(AC23:AD23) -> 0 | AF23: =IF(AE23=1,AC23,0) -> 0 | AG23: =IF(AE23=1,AD23,0) -> 0
AA24: FALSE | AB24: FALSE | AC24: =IF(AA24="","",IF(AA24=TRUE,1,0)) -> 0 | AD24: =IF(AB24="","",IF(AB24=TRUE,1,0)) -> 0 | AE24: =SUM(AC24:AD24) -> 0 | AF24: =IF(AE24=1,AC24,0) -> 0 | AG24: =IF(AE24=1,AD24,0) -> 0
AA25: FALSE | AB25: FALSE | AC25: =IF(AA25="","",IF(AA25=TRUE,1,0)) -> 0 | AD25: =IF(AB25="","",IF(AB25=TRUE,1,0)) -> 0 | AE25: =SUM(AC25:AD25) -> 0 | AF25: =IF(AE25=1,AC25,0) -> 0 | AG25: =IF(AE25=1,AD25,0) -> 0
A26: B. SUPPORT (Targeted Interventions & Differentiated Instruction) | B26: =AF26 -> 0 | C26: =AG26 -> 0 | AC26: =IF(AA26="","",IF(AA26=TRUE,1,0)) | AD26: =IF(AB26="","",IF(AB26=TRUE,1,0)) | AF26: =SUM(AF16:AF25) -> 0 | AG26: =SUM(AG16:AG25) -> 0
A27: Indicator | B27: Yes | C27: No | D27: Remarks/Evidence | AC27: =IF(AA27="","",IF(AA27=TRUE,1,0)) | AD27: =IF(AB27="","",IF(AB27=TRUE,1,0))
A28: 7. Targeted remediation programs are implemented (not general review) | AA28: FALSE | AB28: FALSE | AC28: =IF(AA28="","",IF(AA28=TRUE,1,0)) -> 0 | AD28: =IF(AB28="","",IF(AB28=TRUE,1,0)) -> 0 | AE28: =SUM(AC28:AD28) -> 0 | AF28: =IF(AE28=1,AC28,0) -> 0 | AG28: =IF(AE28=1,AD28,0) -> 0
A29: 8. Learners are grouped based on specific learning gaps | AA29: FALSE | AB29: FALSE | AC29: =IF(AA29="","",IF(AA29=TRUE,1,0)) -> 0 | AD29: =IF(AB29="","",IF(AB29=TRUE,1,0)) -> 0 | AE29: =SUM(AC29:AD29) -> 0 | AF29: =IF(AE29=1,AC29,0) -> 0 | AG29: =IF(AE29=1,AD29,0) -> 0
A30: 9. Differentiated instruction strategies are evident in teaching | AA30: FALSE | AB30: FALSE | AC30: =IF(AA30="","",IF(AA30=TRUE,1,0)) -> 0 | AD30: =IF(AB30="","",IF(AB30=TRUE,1,0)) -> 0 | AE30: =SUM(AC30:AD30) -> 0 | AF30: =IF(AE30=1,AC30,0) -> 0 | AG30: =IF(AE30=1,AD30,0) -> 0
A31: 10. Peer tutoring or learning buddy system is implemented | AA31: FALSE | AB31: FALSE | AC31: =IF(AA31="","",IF(AA31=TRUE,1,0)) -> 0 | AD31: =IF(AB31="","",IF(AB31=TRUE,1,0)) -> 0 | AE31: =SUM(AC31:AD31) -> 0 | AF31: =IF(AE31=1,AC31,0) -> 0 | AG31: =IF(AE31=1,AD31,0) -> 0
A32: 11. Counseling or psychosocial support is provided when needed | AA32: FALSE | AB32: FALSE | AC32: =IF(AA32="","",IF(AA32=TRUE,1,0)) -> 0 | AD32: =IF(AB32="","",IF(AB32=TRUE,1,0)) -> 0 | AE32: =SUM(AC32:AD32) -> 0 | AF32: =IF(AE32=1,AC32,0) -> 0 | AG32: =IF(AE32=1,AD32,0) -> 0
A33: 12. Intervention plans are documented per learner/group | AA33: FALSE | AB33: FALSE | AC33: =IF(AA33="","",IF(AA33=TRUE,1,0)) -> 0 | AD33: =IF(AB33="","",IF(AB33=TRUE,1,0)) -> 0 | AE33: =SUM(AC33:AD33) -> 0 | AF33: =IF(AE33=1,AC33,0) -> 0 | AG33: =IF(AE33=1,AD33,0) -> 0
A34: 13. Appropriate and contextualized learning materials are used | AA34: FALSE | AB34: FALSE | AC34: =IF(AA34="","",IF(AA34=TRUE,1,0)) -> 0 | AD34: =IF(AB34="","",IF(AB34=TRUE,1,0)) -> 0 | AE34: =SUM(AC34:AD34) -> 0 | AF34: =IF(AE34=1,AC34,0) -> 0 | AG34: =IF(AE34=1,AD34,0) -> 0
AA35: FALSE | AB35: FALSE | AC35: =IF(AA35="","",IF(AA35=TRUE,1,0)) -> 0 | AD35: =IF(AB35="","",IF(AB35=TRUE,1,0)) -> 0 | AE35: =SUM(AC35:AD35) -> 0 | AF35: =IF(AE35=1,AC35,0) -> 0 | AG35: =IF(AE35=1,AD35,0) -> 0
AA36: FALSE | AB36: FALSE | AC36: =IF(AA36="","",IF(AA36=TRUE,1,0)) -> 0 | AD36: =IF(AB36="","",IF(AB36=TRUE,1,0)) -> 0 | AE36: =SUM(AC36:AD36) -> 0 | AF36: =IF(AE36=1,AC36,0) -> 0 | AG36: =IF(AE36=1,AD36,0) -> 0
AA37: FALSE | AB37: FALSE | AC37: =IF(AA37="","",IF(AA37=TRUE,1,0)) -> 0 | AD37: =IF(AB37="","",IF(AB37=TRUE,1,0)) -> 0 | AE37: =SUM(AC37:AD37) -> 0 | AF37: =IF(AE37=1,AC37,0) -> 0 | AG37: =IF(AE37=1,AD37,0) -> 0
A38: C. ENGAGE (Safe, Inclusive, and Supportive Environment) | B38: =AF38 -> 0 | C38: =AG38 -> 0 | AC38: =IF(AA38="","",IF(AA38=TRUE,1,0)) | AD38: =IF(AB38="","",IF(AB38=TRUE,1,0)) | AF38: =SUM(AF28:AF37) -> 0 | AG38: =SUM(AG28:AG37) -> 0
A39: Indicator | B39: Yes | C39: No | D39: Remarks/Evidence | AC39: =IF(AA39="","",IF(AA39=TRUE,1,0)) | AD39: =IF(AB39="","",IF(AB39=TRUE,1,0))
A40: 14. SEL (Social-Emotional Learning) is integrated in daily lessons | AA40: FALSE | AB40: FALSE | AC40: =IF(AA40="","",IF(AA40=TRUE,1,0)) -> 0 | AD40: =IF(AB40="","",IF(AB40=TRUE,1,0)) -> 0 | AE40: =SUM(AC40:AD40) -> 0 | AF40: =IF(AE40=1,AC40,0) -> 0 | AG40: =IF(AE40=1,AD40,0) -> 0
A41: 15. Teachers use strategies that develop self- awareness and relationships | AA41: FALSE | AB41: FALSE | AC41: =IF(AA41="","",IF(AA41=TRUE,1,0)) -> 0 | AD41: =IF(AB41="","",IF(AB41=TRUE,1,0)) -> 0 | AE41: =SUM(AC41:AD41) -> 0 | AF41: =IF(AE41=1,AC41,0) -> 0 | AG41: =IF(AE41=1,AD41,0) -> 0
A42: 16. Classroom environment promotes respect and inclusivity | AA42: FALSE | AB42: FALSE | AC42: =IF(AA42="","",IF(AA42=TRUE,1,0)) -> 0 | AD42: =IF(AB42="","",IF(AB42=TRUE,1,0)) -> 0 | AE42: =SUM(AC42:AD42) -> 0 | AF42: =IF(AE42=1,AC42,0) -> 0 | AG42: =IF(AE42=1,AD42,0) -> 0
A43: 17. Positive discipline practices are observed (no punitive approach) | AA43: FALSE | AB43: FALSE | AC43: =IF(AA43="","",IF(AA43=TRUE,1,0)) -> 0 | AD43: =IF(AB43="","",IF(AB43=TRUE,1,0)) -> 0 | AE43: =SUM(AC43:AD43) -> 0 | AF43: =IF(AE43=1,AC43,0) -> 0 | AG43: =IF(AE43=1,AD43,0) -> 0
A44: 18. Child Protection Committee (CPC) is active and functional | D44: Need to be updated | AA44: FALSE | AB44: FALSE | AC44: =IF(AA44="","",IF(AA44=TRUE,1,0)) -> 0 | AD44: =IF(AB44="","",IF(AB44=TRUE,1,0)) -> 0 | AE44: =SUM(AC44:AD44) -> 0 | AF44: =IF(AE44=1,AC44,0) -> 0 | AG44: =IF(AE44=1,AD44,0) -> 0
A45: 19. Anti-bullying and child protection programs are implemented | AA45: FALSE | AB45: FALSE | AC45: =IF(AA45="","",IF(AA45=TRUE,1,0)) -> 0 | AD45: =IF(AB45="","",IF(AB45=TRUE,1,0)) -> 0 | AE45: =SUM(AC45:AD45) -> 0 | AF45: =IF(AE45=1,AC45,0) -> 0 | AG45: =IF(AE45=1,AD45,0) -> 0
A46: 20. Learners are given opportunities to express ideas and feelings | AA46: FALSE | AB46: FALSE | AC46: =IF(AA46="","",IF(AA46=TRUE,1,0)) -> 0 | AD46: =IF(AB46="","",IF(AB46=TRUE,1,0)) -> 0 | AE46: =SUM(AC46:AD46) -> 0 | AF46: =IF(AE46=1,AC46,0) -> 0 | AG46: =IF(AE46=1,AD46,0) -> 0
...

Sheet SUMMARY
A5: Republic of the Philippines
A6: Department of Education
A8: SCHOOLS DIVISION OF MANDAUE CITY
A10: LEARNER DEVELOPMENT AND PROTECTION MONITORING CHECKLIST
A12: SCHOOL | B12: =IF('TABOK ES I'!$A$14="","",'TABOK ES I'!$A$14) | I12: Weighted Mean | J12: Description | K12: =IF('TABOK ES I'!$A$26="","",'TABOK ES I'!$A$26) | R12: Weighted Mean | S12: Description | T12: =IF('TABOK ES I'!$A$38="","",'TABOK ES I'!$A$38) | AA12: Weighted Mean | AB12: Description | AC12: =IF('TABOK ES I'!$A$50="","",'TABOK ES I'!$A$50) | AJ12: Weighted Mean | AK12: Description | AL12: =IF('TABOK ES I'!$A$62="","",'TABOK ES I'!$A$62) | AS12: Weighted Mean | AT12: Description | AV12: TOTAL YES | AW12: TOTAL NO
B13: =IF('TABOK ES I'!$A$16<>"","A.1.1","") | C13: =IF('TABOK ES I'!$A$17<>"","A.1.2","") | D13: =IF('TABOK ES I'!$A$18<>"","A.1.3","") | E13: =IF('TABOK ES I'!$A$19<>"","A.1.4","") | F13: =IF('TABOK ES I'!$A$20<>"","A.1.5","") | G13: =IF('TABOK ES I'!$A$21<>"","A.1.6","") | K13: =IF('TABOK ES I'!$A$28<>"","B.1.1","") | L13: =IF('TABOK ES I'!$A$29<>"","B.1.2","") | M13: =IF('TABOK ES I'!$A$30<>"","B.1.3","") | N13: =IF('TABOK ES I'!$A$31<>"","B.1.4","") | O13: =IF('TABOK ES I'!$A$32<>"","B.1.5","") | P13: =IF('TABOK ES I'!$A$33<>"","B.1.6","") | Q13: =IF('TABOK ES I'!$A$34<>"","B.1.7","") | T13: =IF('TABOK ES I'!$A$40<>"","C.1.1","") | U13: =IF('TABOK ES I'!$A$41<>"","C.1.2","") | V13: =IF('TABOK ES I'!$A$42<>"","C.1.3","") | W13: =IF('TABOK ES I'!$A$43<>"","C.1.4","") | X13: =IF('TABOK ES I'!$A$44<>"","C.1.5","") | Y13: =IF('TABOK ES I'!$A$45<>"","C.1.6","") | Z13: =IF('TABOK ES I'!$A$46<>"","C.1.7","") | AC13: =IF('TABOK ES I'!$A$52<>"","D.1.1","") | AD13: =IF('TABOK ES I'!$A$53<>"","D.1.2","") | AE13: =IF('TABOK ES I'!$A$54<>"","D.1.3","") | AF13: =IF('TABOK ES I'!$A$55<>"","D.1.4","") | AG13: =IF('TABOK ES I'!$A$56<>"","D.1.5","") | AH13: =IF('TABOK ES I'!$A$57<>"","D.1.6","") | AL13: =IF('TABOK ES I'!$A$64<>"","E.1.1","") | AM13: =IF('TABOK ES I'!$A$65<>"","E.1.2","") | AN13: =IF('TABOK ES I'!$A$66<>"","E.1.3","") | AO13: =IF('TABOK ES I'!$A$67<>"","E.1.4","") | AP13: =IF('TABOK ES I'!$A$68<>"","E.1.5","") | AQ13: =IF('TABOK ES I'!$A$69<>"","E.1.6","")
A14: =IF('MAGUIKAY ES'!$B$11="","MAGUIKAY ELEMENTARY SCHOOL",'MAGUIKAY ES'!$B$11) | B14: =IF(AND('MAGUIKAY ES'!$AA$16=TRUE,'MAGUIKAY ES'!$AB$16<>TRUE),1,IF(AND('MAGUIKAY ES'!$AB$16=TRUE,'MAGUIKAY ES'!$AA$16<>TRUE),2,"")) | C14: =IF(AND('MAGUIKAY ES'!$AA$17=TRUE,'MAGUIKAY ES'!$AB$17<>TRUE),1,IF(AND('MAGUIKAY ES'!$AB$17=TRUE,'MAGUIKAY ES'!$AA$17<>TRUE),2,"")) | D14: =IF(AND('MAGUIKAY ES'!$AA$18=TRUE,'MAGUIKAY ES'!$AB$18<>TRUE),1,IF(AND('MAGUIKAY ES'!$AB$18=TRUE,'MAGUIKAY ES'!$AA$18<>TRUE),2,"")) | E14: =IF(AND('MAGUIKAY ES'!$AA$19=TRUE,'MAGUIKAY ES'!$AB$19<>TRUE),1,IF(AND('MAGUIKAY ES'!$AB$19=TRUE,'MAGUIKAY ES'!$AA$19<>TRUE),2,"")) | F14: =IF(AND('MAGUIKAY ES'!$AA$20=TRUE,'MAGUIKAY ES'!$AB$20<>TRUE),1,IF(AND('MAGUIKAY ES'!$AB$20=TRUE,'MAGUIKAY ES'!$AA$20<>TRUE),2,"")) | G14: =IF(AND('MAGUIKAY ES'!$AA$21=TRUE,'MAGUIKAY ES'!$AB$21<>TRUE),1,IF(AND('MAGUIKAY ES'!$AB$21=TRUE,'MAGUIKAY ES'!$AA$21<>TRUE),2,"")) | I14: =IFERROR(ROUND(AVERAGE(B14:H14),2), "") | J14: =IF(I14="","",VLOOKUP(I14,$CH$14:$CK$17,3)) | K14: =IF(AND('MAGUIKAY ES'!$AA$28=TRUE,'MAGUIKAY ES'!$AB$28<>TRUE),1,IF(AND('MAGUIKAY ES'!$AB$28=TRUE,'MAGUIKAY ES'!$AA$28<>TRUE),2,"")) | L14: =IF(AND('MAGUIKAY ES'!$AA$29=TRUE,'MAGUIKAY ES'!$AB$29<>TRUE),1,IF(AND('MAGUIKAY ES'!$AB$29=TRUE,'MAGUIKAY ES'!$AA$29<>TRUE),2,"")) | M14: =IF(AND('MAGUIKAY ES'!$AA$30=TRUE,'MAGUIKAY ES'!$AB$30<>TRUE),1,IF(AND('MAGUIKAY ES'!$AB$30=TRUE,'MAGUIKAY ES'!$AA$30<>TRUE),2,"")) | N14: =IF(AND('MAGUIKAY ES'!$AA$31=TRUE,'MAGUIKAY ES'!$AB$31<>TRUE),1,IF(AND('MAGUIKAY ES'!$AB$31=TRUE,'MAGUIKAY ES'!$AA$31<>TRUE),2,"")) | O14: =IF(AND('MAGUIKAY ES'!$AA$32=TRUE,'MAGUIKAY ES'!$AB$32<>TRUE),1,IF(AND('MAGUIKAY ES'!$AB$32=TRUE,'MAGUIKAY ES'!$AA$32<>TRUE),2,"")) | P14: =IF(AND('MAGUIKAY ES'!$AA$33=TRUE,'MAGUIKAY ES'!$AB$33<>TRUE),1,IF(AND('MAGUIKAY ES'!$AB$33=TRUE,'MAGUIKAY ES'!$AA$33<>TRUE),2,"")) | Q14: =IF(AND('MAGUIKAY ES'!$AA$34=TRUE,'MAGUIKAY ES'!$AB$34<>TRUE),1,IF(AND('MAGUIKAY ES'!$AB$34=TRUE,'MAGUIKAY ES'!$AA$34<>TRUE),2,"")) | R14: =IFERROR(ROUND(AVERAGE(K14:Q14),2), "") | S14: =IF(R14="","",VLOOKUP(R14,$CH$14:$CK$17,3)) | T14: =IF(AND('MAGUIKAY ES'!$AA$40=TRUE,'MAGUIKAY ES'!$AB$40<>TRUE),1,IF(AND('MAGUIKAY ES'!$AB$40=TRUE,'MAGUIKAY ES'!$AA$40<>TRUE),2,"")) | U14: =IF(AND('MAGUIKAY ES'!$AA$41=TRUE,'MAGUIKAY ES'!$AB$41<>TRUE),1,IF(AND('MAGUIKAY ES'!$AB$41=TRUE,'MAGUIKAY ES'!$AA$41<>TRUE),2,"")) | V14: =IF(AND('MAGUIKAY ES'!$AA$42=TRUE,'MAGUIKAY ES'!$AB$42<>TRUE),1,IF(AND('MAGUIKAY ES'!$AB$42=TRUE,'MAGUIKAY ES'!$AA$42<>TRUE),2,"")) | W14: =IF(AND('MAGUIKAY ES'!$AA$43=TRUE,'MAGUIKAY ES'!$AB$43<>TRUE),1,IF(AND('MAGUIKAY ES'!$AB$43=TRUE,'MAGUIKAY ES'!$AA$43<>TRUE),2,"")) | X14: =IF(AND('MAGUIKAY ES'!$AA$44=TRUE,'MAGUIKAY ES'!$AB$44<>TRUE),1,IF(AND('MAGUIKAY ES'!$AB$44=TRUE,'MAGUIKAY ES'!$AA$44<>TRUE),2,"")) | Y14: =IF(AND('MAGUIKAY ES'!$AA$45=TRUE,'MAGUIKAY ES'!$AB$45<>TRUE),1,IF(AND('MAGUIKAY ES'!$AB$45=TRUE,'MAGUIKAY ES'!$AA$45<>TRUE),2,"")) | Z14: =IF(AND('MAGUIKAY ES'!$AA$46=TRUE,'MAGUIKAY ES'!$AB$46<>TRUE),1,IF(AND('MAGUIKAY ES'!$AB$46=TRUE,'MAGUIKAY ES'!$AA$46<>TRUE),2,"")) | AA14: =IFERROR(ROUND(AVERAGE(T14:Z14),2), "") | AB14: =IF(AA14="","",VLOOKUP(AA14,$CH$14:$CK$17,3)) | AC14: =IF(AND('MAGUIKAY ES'!$AA$52=TRUE,'MAGUIKAY ES'!$AB$52<>TRUE),1,IF(AND('MAGUIKAY ES'!$AB$52=TRUE,'MAGUIKAY ES'!$AA$52<>TRUE),2,"")) | AD14: =IF(AND('MAGUIKAY ES'!$AA$53=TRUE,'MAGUIKAY ES'!$AB$53<>TRUE),1,IF(AND('MAGUIKAY ES'!$AB$53=TRUE,'MAGUIKAY ES'!$AA$53<>TRUE),2,"")) | AE14: =IF(AND('MAGUIKAY ES'!$AA$54=TRUE,'MAGUIKAY ES'!$AB$54<>TRUE),1,IF(AND('MAGUIKAY ES'!$AB$54=TRUE,'MAGUIKAY ES'!$AA$54<>TRUE),2,"")) | AF14: =IF(AND('MAGUIKAY ES'!$AA$55=TRUE,'MAGUIKAY ES'!$AB$55<>TRUE),1,IF(AND('MAGUIKAY ES'!$AB$55=TRUE,'MAGUIKAY ES'!$AA$55<>TRUE),2,"")) | AG14: =IF(AND('MAGUIKAY ES'!$AA$56=TRUE,'MAGUIKAY ES'!$AB$56<>TRUE),1,IF(AND('MAGUIKAY ES'!$AB$56=TRUE,'MAGUIKAY ES'!$AA$56<>TRUE),2,"")) | AH14: =IF(AND('MAGUIKAY ES'!$AA$57=TRUE,'MAGUIKAY ES'!$AB$57<>TRUE),1,IF(AND('MAGUIKAY ES'!$AB$57=TRUE,'MAGUIKAY ES'!$AA$57<>TRUE),2,"")) | AJ14: =IFERROR(ROUND(AVERAGE(AC14:AI14),2), "") | AK14: =IF(AJ14="","",VLOOKUP(AJ14,$CH$14:$CK$17,3)) | AL14: =IF(AND('MAGUIKAY ES'!$AA$64=TRUE,'MAGUIKAY ES'!$AB$64<>TRUE),1,IF(AND('MAGUIKAY ES'!$AB$64=TRUE,'MAGUIKAY ES'!$AA$64<>TRUE),2,"")) | AM14: =IF(AND('MAGUIKAY ES'!$AA$65=TRUE,'MAGUIKAY ES'!$AB$65<>TRUE),1,IF(AND('MAGUIKAY ES'!$AB$65=TRUE,'MAGUIKAY ES'!$AA$65<>TRUE),2,"")) | AN14: =IF(AND('MAGUIKAY ES'!$AA$66=TRUE,'MAGUIKAY ES'!$AB$66<>TRUE),1,IF(AND('MAGUIKAY ES'!$AB$66=TRUE,'MAGUIKAY ES'!$AA$66<>TRUE),2,"")) | AO14: =IF(AND('MAGUIKAY ES'!$AA$67=TRUE,'MAGUIKAY ES'!$AB$67<>TRUE),1,IF(AND('MAGUIKAY ES'!$AB$67=TRUE,'MAGUIKAY ES'!$AA$67<>TRUE),2,"")) | AP14: =IF(AND('MAGUIKAY ES'!$AA$68=TRUE,'MAGUIKAY ES'!$AB$68<>TRUE),1,IF(AND('MAGUIKAY ES'!$AB$68=TRUE,'MAGUIKAY ES'!$AA$68<>TRUE),2,"")) | AQ14: =IF(AND('MAGUIKAY ES'!$AA$69=TRUE,'MAGUIKAY ES'!$AB$69<>TRUE),1,IF(AND('MAGUIKAY ES'!$AB$69=TRUE,'MAGUIKAY ES'!$AA$69<>TRUE),2,"")) | AS14: =IFERROR(ROUND(AVERAGE(AL14:AR14),2), "") | AT14: =IF(AS14="","",VLOOKUP(AS14,$CH$14:$CK$17,3)) | AV14: =COUNTIF(B14:H14,1)+COUNTIF(K14:Q14,1)+COUNTIF(T14:Z14,1)+COUNTIF(AC14:AI14,1)+COUNTIF(AL14:AR14,1) | AW14: =COUNTIF(B14:H14,2)+COUNTIF(K14:Q14,2)+COUNTIF(T14:Z14,2)+COUNTIF(AC14:AI14,2)+COUNTIF(AL14:AR14,2) | CH14: 1 | CI14: 1.25 | CJ14: Fully Implemented
